ERROR 2025-07-09 11:49:25,612 log Internal Server Error: /randevu/tablo/
Traceback (most recent call last):
  File "C:\Users\asuma\AppData\Local\Programs\Python\Python312\Lib\site-packages\django\core\handlers\exception.py", line 47, in inner
    response = get_response(request)
               ^^^^^^^^^^^^^^^^^^^^^
  File "C:\Users\asuma\AppData\Local\Programs\Python\Python312\Lib\site-packages\django\core\handlers\base.py", line 181, in _get_response
    response = wrapped_callback(request, *callback_args, **callback_kwargs)
               ^^^^^^^^^^^^^^^^^^^^^^^^^^^^^^^^^^^^^^^^^^^^^^^^^^^^^^^^^^^^
  File "C:\Users\asuma\OneDrive\Masaüstü\HastaneYonetimProjesi\hastane\views\appointment_views.py", line 279, in appointment_table_partial
    return render(request, 'hastane/appointment_table_partial.html', {'appointments': appointments})
           ^^^^^^^^^^^^^^^^^^^^^^^^^^^^^^^^^^^^^^^^^^^^^^^^^^^^^^^^^^^^^^^^^^^^^^^^^^^^^^^^^^^^^^^^^
  File "C:\Users\asuma\AppData\Local\Programs\Python\Python312\Lib\site-packages\django\shortcuts.py", line 19, in render
    content = loader.render_to_string(template_name, context, request, using=using)
              ^^^^^^^^^^^^^^^^^^^^^^^^^^^^^^^^^^^^^^^^^^^^^^^^^^^^^^^^^^^^^^^^^^^^^
  File "C:\Users\asuma\AppData\Local\Programs\Python\Python312\Lib\site-packages\django\template\loader.py", line 61, in render_to_string
    template = get_template(template_name, using=using)
               ^^^^^^^^^^^^^^^^^^^^^^^^^^^^^^^^^^^^^^^^
  File "C:\Users\asuma\AppData\Local\Programs\Python\Python312\Lib\site-packages\django\template\loader.py", line 19, in get_template
    raise TemplateDoesNotExist(template_name, chain=chain)
django.template.exceptions.TemplateDoesNotExist: hastane/appointment_table_partial.html
ERROR 2025-07-09 11:49:25,619 basehttp "GET /randevu/tablo/ HTTP/1.1" 500 82223
ERROR 2025-07-09 13:16:53,347 log Internal Server Error: /randevu/ekle/
Traceback (most recent call last):
  File "C:\Users\asuma\AppData\Local\Programs\Python\Python312\Lib\site-packages\django\core\handlers\exception.py", line 47, in inner
    response = get_response(request)
               ^^^^^^^^^^^^^^^^^^^^^
  File "C:\Users\asuma\AppData\Local\Programs\Python\Python312\Lib\site-packages\django\core\handlers\base.py", line 181, in _get_response
    response = wrapped_callback(request, *callback_args, **callback_kwargs)
               ^^^^^^^^^^^^^^^^^^^^^^^^^^^^^^^^^^^^^^^^^^^^^^^^^^^^^^^^^^^^
  File "C:\Users\asuma\OneDrive\Masaüstü\HastaneYonetimProjesi\hastane\views\appointment_views.py", line 239, in appointment_create
    html = render_to_string('hastane/appointment_form.html', {
           ^^^^^^^^^^^^^^^^^^^^^^^^^^^^^^^^^^^^^^^^^^^^^^^^^^^
  File "C:\Users\asuma\AppData\Local\Programs\Python\Python312\Lib\site-packages\django\template\loader.py", line 61, in render_to_string
    template = get_template(template_name, using=using)
               ^^^^^^^^^^^^^^^^^^^^^^^^^^^^^^^^^^^^^^^^
  File "C:\Users\asuma\AppData\Local\Programs\Python\Python312\Lib\site-packages\django\template\loader.py", line 19, in get_template
    raise TemplateDoesNotExist(template_name, chain=chain)
django.template.exceptions.TemplateDoesNotExist: hastane/appointment_form.html
ERROR 2025-07-09 13:16:53,347 basehttp "GET /randevu/ekle/?appointment_id=9 HTTP/1.1" 500 78506
ERROR 2025-07-09 13:16:53,784 log Internal Server Error: /randevu/ekle/
Traceback (most recent call last):
  File "C:\Users\asuma\AppData\Local\Programs\Python\Python312\Lib\site-packages\django\core\handlers\exception.py", line 47, in inner
    response = get_response(request)
               ^^^^^^^^^^^^^^^^^^^^^
  File "C:\Users\asuma\AppData\Local\Programs\Python\Python312\Lib\site-packages\django\core\handlers\base.py", line 181, in _get_response
    response = wrapped_callback(request, *callback_args, **callback_kwargs)
               ^^^^^^^^^^^^^^^^^^^^^^^^^^^^^^^^^^^^^^^^^^^^^^^^^^^^^^^^^^^^
  File "C:\Users\asuma\OneDrive\Masaüstü\HastaneYonetimProjesi\hastane\views\appointment_views.py", line 239, in appointment_create
    html = render_to_string('hastane/appointment_form.html', {
           ^^^^^^^^^^^^^^^^^^^^^^^^^^^^^^^^^^^^^^^^^^^^^^^^^^^
  File "C:\Users\asuma\AppData\Local\Programs\Python\Python312\Lib\site-packages\django\template\loader.py", line 61, in render_to_string
    template = get_template(template_name, using=using)
               ^^^^^^^^^^^^^^^^^^^^^^^^^^^^^^^^^^^^^^^^
  File "C:\Users\asuma\AppData\Local\Programs\Python\Python312\Lib\site-packages\django\template\loader.py", line 19, in get_template
    raise TemplateDoesNotExist(template_name, chain=chain)
django.template.exceptions.TemplateDoesNotExist: hastane/appointment_form.html
ERROR 2025-07-09 13:16:53,784 basehttp "GET /randevu/ekle/?appointment_id=9 HTTP/1.1" 500 78506
ERROR 2025-07-09 13:16:53,984 log Internal Server Error: /randevu/ekle/
Traceback (most recent call last):
  File "C:\Users\asuma\AppData\Local\Programs\Python\Python312\Lib\site-packages\django\core\handlers\exception.py", line 47, in inner
    response = get_response(request)
               ^^^^^^^^^^^^^^^^^^^^^
  File "C:\Users\asuma\AppData\Local\Programs\Python\Python312\Lib\site-packages\django\core\handlers\base.py", line 181, in _get_response
    response = wrapped_callback(request, *callback_args, **callback_kwargs)
               ^^^^^^^^^^^^^^^^^^^^^^^^^^^^^^^^^^^^^^^^^^^^^^^^^^^^^^^^^^^^
  File "C:\Users\asuma\OneDrive\Masaüstü\HastaneYonetimProjesi\hastane\views\appointment_views.py", line 239, in appointment_create
    html = render_to_string('hastane/appointment_form.html', {
           ^^^^^^^^^^^^^^^^^^^^^^^^^^^^^^^^^^^^^^^^^^^^^^^^^^^
  File "C:\Users\asuma\AppData\Local\Programs\Python\Python312\Lib\site-packages\django\template\loader.py", line 61, in render_to_string
    template = get_template(template_name, using=using)
               ^^^^^^^^^^^^^^^^^^^^^^^^^^^^^^^^^^^^^^^^
  File "C:\Users\asuma\AppData\Local\Programs\Python\Python312\Lib\site-packages\django\template\loader.py", line 19, in get_template
    raise TemplateDoesNotExist(template_name, chain=chain)
django.template.exceptions.TemplateDoesNotExist: hastane/appointment_form.html
ERROR 2025-07-09 13:16:53,984 basehttp "GET /randevu/ekle/?appointment_id=9 HTTP/1.1" 500 78506
ERROR 2025-07-09 13:16:54,142 log Internal Server Error: /randevu/ekle/
Traceback (most recent call last):
  File "C:\Users\asuma\AppData\Local\Programs\Python\Python312\Lib\site-packages\django\core\handlers\exception.py", line 47, in inner
    response = get_response(request)
               ^^^^^^^^^^^^^^^^^^^^^
  File "C:\Users\asuma\AppData\Local\Programs\Python\Python312\Lib\site-packages\django\core\handlers\base.py", line 181, in _get_response
    response = wrapped_callback(request, *callback_args, **callback_kwargs)
               ^^^^^^^^^^^^^^^^^^^^^^^^^^^^^^^^^^^^^^^^^^^^^^^^^^^^^^^^^^^^
  File "C:\Users\asuma\OneDrive\Masaüstü\HastaneYonetimProjesi\hastane\views\appointment_views.py", line 239, in appointment_create
    html = render_to_string('hastane/appointment_form.html', {
           ^^^^^^^^^^^^^^^^^^^^^^^^^^^^^^^^^^^^^^^^^^^^^^^^^^^
  File "C:\Users\asuma\AppData\Local\Programs\Python\Python312\Lib\site-packages\django\template\loader.py", line 61, in render_to_string
    template = get_template(template_name, using=using)
               ^^^^^^^^^^^^^^^^^^^^^^^^^^^^^^^^^^^^^^^^
  File "C:\Users\asuma\AppData\Local\Programs\Python\Python312\Lib\site-packages\django\template\loader.py", line 19, in get_template
    raise TemplateDoesNotExist(template_name, chain=chain)
django.template.exceptions.TemplateDoesNotExist: hastane/appointment_form.html
ERROR 2025-07-09 13:16:54,142 basehttp "GET /randevu/ekle/?appointment_id=9 HTTP/1.1" 500 78506
ERROR 2025-07-09 13:16:57,321 log Internal Server Error: /randevu/ekle/
Traceback (most recent call last):
  File "C:\Users\asuma\AppData\Local\Programs\Python\Python312\Lib\site-packages\django\core\handlers\exception.py", line 47, in inner
    response = get_response(request)
               ^^^^^^^^^^^^^^^^^^^^^
  File "C:\Users\asuma\AppData\Local\Programs\Python\Python312\Lib\site-packages\django\core\handlers\base.py", line 181, in _get_response
    response = wrapped_callback(request, *callback_args, **callback_kwargs)
               ^^^^^^^^^^^^^^^^^^^^^^^^^^^^^^^^^^^^^^^^^^^^^^^^^^^^^^^^^^^^
  File "C:\Users\asuma\OneDrive\Masaüstü\HastaneYonetimProjesi\hastane\views\appointment_views.py", line 239, in appointment_create
    html = render_to_string('hastane/appointment_form.html', {
           ^^^^^^^^^^^^^^^^^^^^^^^^^^^^^^^^^^^^^^^^^^^^^^^^^^^
  File "C:\Users\asuma\AppData\Local\Programs\Python\Python312\Lib\site-packages\django\template\loader.py", line 61, in render_to_string
    template = get_template(template_name, using=using)
               ^^^^^^^^^^^^^^^^^^^^^^^^^^^^^^^^^^^^^^^^
  File "C:\Users\asuma\AppData\Local\Programs\Python\Python312\Lib\site-packages\django\template\loader.py", line 19, in get_template
    raise TemplateDoesNotExist(template_name, chain=chain)
django.template.exceptions.TemplateDoesNotExist: hastane/appointment_form.html
ERROR 2025-07-09 13:16:57,321 basehttp "GET /randevu/ekle/?appointment_id=9 HTTP/1.1" 500 78526
ERROR 2025-07-09 13:45:32,394 log Internal Server Error: /randevu/doktor-uygunluk/7/
Traceback (most recent call last):
  File "C:\Users\asuma\AppData\Local\Programs\Python\Python312\Lib\site-packages\django\core\handlers\exception.py", line 47, in inner
    response = get_response(request)
               ^^^^^^^^^^^^^^^^^^^^^
  File "C:\Users\asuma\AppData\Local\Programs\Python\Python312\Lib\site-packages\django\core\handlers\base.py", line 181, in _get_response
    response = wrapped_callback(request, *callback_args, **callback_kwargs)
               ^^^^^^^^^^^^^^^^^^^^^^^^^^^^^^^^^^^^^^^^^^^^^^^^^^^^^^^^^^^^
  File "C:\Users\asuma\OneDrive\Masaüstü\HastaneYonetimProjesi\hastane\views\appointment_views.py", line 124, in check_doctor_availability
    'speciality': doctor.speciality
                  ^^^^^^^^^^^^^^^^^
AttributeError: 'Doctors' object has no attribute 'speciality'
ERROR 2025-07-09 13:45:32,512 basehttp "GET /randevu/doktor-uygunluk/7/?date=2025-07-31&time=11%3A00&appointment_id=9 HTTP/1.1" 500 69319
ERROR 2025-07-31 16:26:11,621 log Internal Server Error: /login/doctor/
Traceback (most recent call last):
  File "C:\Users\ASUS\anaconda3\Lib\site-packages\django\core\handlers\exception.py", line 47, in inner
    response = get_response(request)
               ^^^^^^^^^^^^^^^^^^^^^
  File "C:\Users\ASUS\anaconda3\Lib\site-packages\django\core\handlers\base.py", line 181, in _get_response
    response = wrapped_callback(request, *callback_args, **callback_kwargs)
               ^^^^^^^^^^^^^^^^^^^^^^^^^^^^^^^^^^^^^^^^^^^^^^^^^^^^^^^^^^^^
  File "C:\Users\ASUS\Desktop\HastaneYonetim\HastaneYonetimProjesi\hastane\views\login_views.py", line 39, in doctor_login_view
    if check_password(password, doctor.password):
                                ^^^^^^^^^^^^^^^
AttributeError: 'Doctors' object has no attribute 'password'
ERROR 2025-07-31 16:26:11,621 basehttp "POST /login/doctor/ HTTP/1.1" 500 70376
ERROR 2025-07-31 16:30:23,177 log Internal Server Error: /doctor/dashboard/
Traceback (most recent call last):
  File "C:\Users\ASUS\anaconda3\Lib\site-packages\django\core\handlers\exception.py", line 47, in inner
    response = get_response(request)
               ^^^^^^^^^^^^^^^^^^^^^
  File "C:\Users\ASUS\anaconda3\Lib\site-packages\django\core\handlers\base.py", line 181, in _get_response
    response = wrapped_callback(request, *callback_args, **callback_kwargs)
               ^^^^^^^^^^^^^^^^^^^^^^^^^^^^^^^^^^^^^^^^^^^^^^^^^^^^^^^^^^^^
  File "C:\Users\ASUS\Desktop\HastaneYonetim\HastaneYonetimProjesi\hastane\views\login_views.py", line 66, in doctor_dashboard_view
    return render(request, 'doctor_dashboard.html', context)
           ^^^^^^^^^^^^^^^^^^^^^^^^^^^^^^^^^^^^^^^^^^^^^^^^^
  File "C:\Users\ASUS\anaconda3\Lib\site-packages\django\shortcuts.py", line 19, in render
    content = loader.render_to_string(template_name, context, request, using=using)
              ^^^^^^^^^^^^^^^^^^^^^^^^^^^^^^^^^^^^^^^^^^^^^^^^^^^^^^^^^^^^^^^^^^^^^
  File "C:\Users\ASUS\anaconda3\Lib\site-packages\django\template\loader.py", line 62, in render_to_string
    return template.render(context, request)
           ^^^^^^^^^^^^^^^^^^^^^^^^^^^^^^^^^
  File "C:\Users\ASUS\anaconda3\Lib\site-packages\django\template\backends\django.py", line 61, in render
    return self.template.render(context)
           ^^^^^^^^^^^^^^^^^^^^^^^^^^^^^
  File "C:\Users\ASUS\anaconda3\Lib\site-packages\django\template\base.py", line 170, in render
    return self._render(context)
           ^^^^^^^^^^^^^^^^^^^^^
  File "C:\Users\ASUS\anaconda3\Lib\site-packages\django\template\base.py", line 162, in _render
    return self.nodelist.render(context)
           ^^^^^^^^^^^^^^^^^^^^^^^^^^^^^
  File "C:\Users\ASUS\anaconda3\Lib\site-packages\django\template\base.py", line 938, in render
    bit = node.render_annotated(context)
          ^^^^^^^^^^^^^^^^^^^^^^^^^^^^^^
  File "C:\Users\ASUS\anaconda3\Lib\site-packages\django\template\base.py", line 905, in render_annotated
    return self.render(context)
           ^^^^^^^^^^^^^^^^^^^^
  File "C:\Users\ASUS\anaconda3\Lib\site-packages\django\template\loader_tags.py", line 150, in render
    return compiled_parent._render(context)
           ^^^^^^^^^^^^^^^^^^^^^^^^^^^^^^^^
  File "C:\Users\ASUS\anaconda3\Lib\site-packages\django\template\base.py", line 162, in _render
    return self.nodelist.render(context)
           ^^^^^^^^^^^^^^^^^^^^^^^^^^^^^
  File "C:\Users\ASUS\anaconda3\Lib\site-packages\django\template\base.py", line 938, in render
    bit = node.render_annotated(context)
          ^^^^^^^^^^^^^^^^^^^^^^^^^^^^^^
  File "C:\Users\ASUS\anaconda3\Lib\site-packages\django\template\base.py", line 905, in render_annotated
    return self.render(context)
           ^^^^^^^^^^^^^^^^^^^^
  File "C:\Users\ASUS\anaconda3\Lib\site-packages\django\template\loader_tags.py", line 62, in render
    result = block.nodelist.render(context)
             ^^^^^^^^^^^^^^^^^^^^^^^^^^^^^^
  File "C:\Users\ASUS\anaconda3\Lib\site-packages\django\template\base.py", line 938, in render
    bit = node.render_annotated(context)
          ^^^^^^^^^^^^^^^^^^^^^^^^^^^^^^
  File "C:\Users\ASUS\anaconda3\Lib\site-packages\django\template\base.py", line 905, in render_annotated
    return self.render(context)
           ^^^^^^^^^^^^^^^^^^^^
  File "C:\Users\ASUS\anaconda3\Lib\site-packages\django\template\defaulttags.py", line 446, in render
    url = reverse(view_name, args=args, kwargs=kwargs, current_app=current_app)
          ^^^^^^^^^^^^^^^^^^^^^^^^^^^^^^^^^^^^^^^^^^^^^^^^^^^^^^^^^^^^^^^^^^^^^
  File "C:\Users\ASUS\anaconda3\Lib\site-packages\django\urls\base.py", line 86, in reverse
    return resolver._reverse_with_prefix(view, prefix, *args, **kwargs)
           ^^^^^^^^^^^^^^^^^^^^^^^^^^^^^^^^^^^^^^^^^^^^^^^^^^^^^^^^^^^^
  File "C:\Users\ASUS\anaconda3\Lib\site-packages\django\urls\resolvers.py", line 694, in _reverse_with_prefix
    raise NoReverseMatch(msg)
django.urls.exceptions.NoReverseMatch: Reverse for 'patients' not found. 'patients' is not a valid view function or pattern name.
ERROR 2025-07-31 16:30:23,193 basehttp "GET /doctor/dashboard/ HTTP/1.1" 500 164606
ERROR 2025-07-31 18:18:46,017 log Internal Server Error: /patients/
ERROR 2025-07-31 18:18:46,019 basehttp "POST /patients/ HTTP/1.1" 500 37
ERROR 2025-07-31 18:19:00,430 log Internal Server Error: /patients/
ERROR 2025-07-31 18:19:00,430 basehttp "POST /patients/ HTTP/1.1" 500 37
ERROR 2025-07-31 18:20:13,337 log Internal Server Error: /patients/
ERROR 2025-07-31 18:20:13,338 basehttp "POST /patients/ HTTP/1.1" 500 37
ERROR 2025-07-31 18:20:21,321 log Internal Server Error: /patients/
ERROR 2025-07-31 18:20:21,322 basehttp "POST /patients/ HTTP/1.1" 500 37
ERROR 2025-07-31 18:20:58,255 log Internal Server Error: /patients/
ERROR 2025-07-31 18:20:58,256 basehttp "POST /patients/ HTTP/1.1" 500 37
ERROR 2025-07-31 18:21:10,274 log Internal Server Error: /patients/
ERROR 2025-07-31 18:21:10,275 basehttp "POST /patients/ HTTP/1.1" 500 37
