ERROR 2025-07-09 14:47:36,082 log Internal Server Error: /
Traceback (most recent call last):
  File "C:\Users\ASUS\anaconda3\Lib\site-packages\django\template\backends\django.py", line 61, in render
    return self.template.render(context)
           ^^^^^^^^^^^^^^^^^^^^^^^^^^^^^
  File "C:\Users\ASUS\anaconda3\Lib\site-packages\django\template\base.py", line 170, in render
    return self._render(context)
           ^^^^^^^^^^^^^^^^^^^^^
  File "C:\Users\ASUS\anaconda3\Lib\site-packages\django\template\base.py", line 162, in _render
    return self.nodelist.render(context)
           ^^^^^^^^^^^^^^^^^^^^^^^^^^^^^
  File "C:\Users\ASUS\anaconda3\Lib\site-packages\django\template\base.py", line 938, in render
    bit = node.render_annotated(context)
          ^^^^^^^^^^^^^^^^^^^^^^^^^^^^^^
  File "C:\Users\ASUS\anaconda3\Lib\site-packages\django\template\base.py", line 905, in render_annotated
    return self.render(context)
           ^^^^^^^^^^^^^^^^^^^^
  File "C:\Users\ASUS\anaconda3\Lib\site-packages\django\template\loader_tags.py", line 127, in render
    compiled_parent = self.get_parent(context)
                      ^^^^^^^^^^^^^^^^^^^^^^^^
  File "C:\Users\ASUS\anaconda3\Lib\site-packages\django\template\loader_tags.py", line 124, in get_parent
    return self.find_template(parent, context)
           ^^^^^^^^^^^^^^^^^^^^^^^^^^^^^^^^^^^
  File "C:\Users\ASUS\anaconda3\Lib\site-packages\django\template\loader_tags.py", line 103, in find_template
    template, origin = context.template.engine.find_template(
                       ^^^^^^^^^^^^^^^^^^^^^^^^^^^^^^^^^^^^^^
  File "C:\Users\ASUS\anaconda3\Lib\site-packages\django\template\engine.py", line 129, in find_template
    raise TemplateDoesNotExist(name, tried=tried)
django.template.exceptions.TemplateDoesNotExist: base_login.html

The above exception was the direct cause of the following exception:

Traceback (most recent call last):
  File "C:\Users\ASUS\anaconda3\Lib\site-packages\django\core\handlers\exception.py", line 47, in inner
    response = get_response(request)
               ^^^^^^^^^^^^^^^^^^^^^
  File "C:\Users\ASUS\anaconda3\Lib\site-packages\django\core\handlers\base.py", line 181, in _get_response
    response = wrapped_callback(request, *callback_args, **callback_kwargs)
               ^^^^^^^^^^^^^^^^^^^^^^^^^^^^^^^^^^^^^^^^^^^^^^^^^^^^^^^^^^^^
  File "C:\Users\ASUS\Desktop\HastaneYonetim\HastaneYonetimProjesi\hastane\views\login_views.py", line 6, in login_select_view
    return render(request, 'loginpage/login_select.html')
           ^^^^^^^^^^^^^^^^^^^^^^^^^^^^^^^^^^^^^^^^^^^^^^
  File "C:\Users\ASUS\anaconda3\Lib\site-packages\django\shortcuts.py", line 19, in render
    content = loader.render_to_string(template_name, context, request, using=using)
              ^^^^^^^^^^^^^^^^^^^^^^^^^^^^^^^^^^^^^^^^^^^^^^^^^^^^^^^^^^^^^^^^^^^^^
  File "C:\Users\ASUS\anaconda3\Lib\site-packages\django\template\loader.py", line 62, in render_to_string
    return template.render(context, request)
           ^^^^^^^^^^^^^^^^^^^^^^^^^^^^^^^^^
  File "C:\Users\ASUS\anaconda3\Lib\site-packages\django\template\backends\django.py", line 63, in render
    reraise(exc, self.backend)
  File "C:\Users\ASUS\anaconda3\Lib\site-packages\django\template\backends\django.py", line 84, in reraise
    raise new from exc
django.template.exceptions.TemplateDoesNotExist: base_login.html
ERROR 2025-07-09 14:47:36,102 basehttp "GET / HTTP/1.1" 500 125711
ERROR 2025-07-09 14:48:06,081 log Internal Server Error: /api/polyclinics/
Traceback (most recent call last):
  File "C:\Users\ASUS\anaconda3\Lib\site-packages\django\db\backends\base\base.py", line 219, in ensure_connection
    self.connect()
  File "C:\Users\ASUS\anaconda3\Lib\site-packages\django\utils\asyncio.py", line 26, in inner
    return func(*args, **kwargs)
           ^^^^^^^^^^^^^^^^^^^^^
  File "C:\Users\ASUS\anaconda3\Lib\site-packages\django\db\backends\base\base.py", line 200, in connect
    self.connection = self.get_new_connection(conn_params)
                      ^^^^^^^^^^^^^^^^^^^^^^^^^^^^^^^^^^^^
  File "C:\Users\ASUS\anaconda3\Lib\site-packages\django\utils\asyncio.py", line 26, in inner
    return func(*args, **kwargs)
           ^^^^^^^^^^^^^^^^^^^^^
  File "C:\Users\ASUS\anaconda3\Lib\site-packages\django\db\backends\mysql\base.py", line 234, in get_new_connection
    connection = Database.connect(**conn_params)
                 ^^^^^^^^^^^^^^^^^^^^^^^^^^^^^^^
  File "C:\Users\ASUS\anaconda3\Lib\site-packages\MySQLdb\__init__.py", line 121, in Connect
    return Connection(*args, **kwargs)
           ^^^^^^^^^^^^^^^^^^^^^^^^^^^
  File "C:\Users\ASUS\anaconda3\Lib\site-packages\MySQLdb\connections.py", line 200, in __init__
    super().__init__(*args, **kwargs2)
MySQLdb.OperationalError: (2002, "Can't connect to server on 'localhost' (10061)")

The above exception was the direct cause of the following exception:

Traceback (most recent call last):
  File "C:\Users\ASUS\anaconda3\Lib\site-packages\django\core\handlers\exception.py", line 47, in inner
    response = get_response(request)
               ^^^^^^^^^^^^^^^^^^^^^
  File "C:\Users\ASUS\anaconda3\Lib\site-packages\django\core\handlers\base.py", line 181, in _get_response
    response = wrapped_callback(request, *callback_args, **callback_kwargs)
               ^^^^^^^^^^^^^^^^^^^^^^^^^^^^^^^^^^^^^^^^^^^^^^^^^^^^^^^^^^^^
  File "C:\Users\ASUS\anaconda3\Lib\site-packages\django\views\decorators\csrf.py", line 54, in wrapped_view
    return view_func(*args, **kwargs)
           ^^^^^^^^^^^^^^^^^^^^^^^^^^
  File "C:\Users\ASUS\anaconda3\Lib\site-packages\django\views\decorators\http.py", line 40, in inner
    return func(request, *args, **kwargs)
           ^^^^^^^^^^^^^^^^^^^^^^^^^^^^^^
  File "C:\Users\ASUS\Desktop\HastaneYonetim\HastaneYonetimProjesi\hastane\views\polyclinic_api.py", line 12, in polyclinic_api
    return JsonResponse(list(clinics), safe=False)
                        ^^^^^^^^^^^^^
  File "C:\Users\ASUS\anaconda3\Lib\site-packages\django\db\models\query.py", line 280, in __iter__
    self._fetch_all()
  File "C:\Users\ASUS\anaconda3\Lib\site-packages\django\db\models\query.py", line 1324, in _fetch_all
    self._result_cache = list(self._iterable_class(self))
                         ^^^^^^^^^^^^^^^^^^^^^^^^^^^^^^^^
  File "C:\Users\ASUS\anaconda3\Lib\site-packages\django\db\models\query.py", line 109, in __iter__
    for row in compiler.results_iter(chunked_fetch=self.chunked_fetch, chunk_size=self.chunk_size):
               ^^^^^^^^^^^^^^^^^^^^^^^^^^^^^^^^^^^^^^^^^^^^^^^^^^^^^^^^^^^^^^^^^^^^^^^^^^^^^^^^^^^
  File "C:\Users\ASUS\anaconda3\Lib\site-packages\django\db\models\sql\compiler.py", line 1124, in results_iter
    results = self.execute_sql(MULTI, chunked_fetch=chunked_fetch, chunk_size=chunk_size)
              ^^^^^^^^^^^^^^^^^^^^^^^^^^^^^^^^^^^^^^^^^^^^^^^^^^^^^^^^^^^^^^^^^^^^^^^^^^^
  File "C:\Users\ASUS\anaconda3\Lib\site-packages\django\db\models\sql\compiler.py", line 1167, in execute_sql
    cursor = self.connection.cursor()
             ^^^^^^^^^^^^^^^^^^^^^^^^
  File "C:\Users\ASUS\anaconda3\Lib\site-packages\django\utils\asyncio.py", line 26, in inner
    return func(*args, **kwargs)
           ^^^^^^^^^^^^^^^^^^^^^
  File "C:\Users\ASUS\anaconda3\Lib\site-packages\django\db\backends\base\base.py", line 259, in cursor
    return self._cursor()
           ^^^^^^^^^^^^^^
  File "C:\Users\ASUS\anaconda3\Lib\site-packages\django\db\backends\base\base.py", line 235, in _cursor
    self.ensure_connection()
  File "C:\Users\ASUS\anaconda3\Lib\site-packages\django\utils\asyncio.py", line 26, in inner
    return func(*args, **kwargs)
           ^^^^^^^^^^^^^^^^^^^^^
  File "C:\Users\ASUS\anaconda3\Lib\site-packages\django\db\backends\base\base.py", line 218, in ensure_connection
    with self.wrap_database_errors:
  File "C:\Users\ASUS\anaconda3\Lib\site-packages\django\db\utils.py", line 90, in __exit__
    raise dj_exc_value.with_traceback(traceback) from exc_value
  File "C:\Users\ASUS\anaconda3\Lib\site-packages\django\db\backends\base\base.py", line 219, in ensure_connection
    self.connect()
  File "C:\Users\ASUS\anaconda3\Lib\site-packages\django\utils\asyncio.py", line 26, in inner
    return func(*args, **kwargs)
           ^^^^^^^^^^^^^^^^^^^^^
  File "C:\Users\ASUS\anaconda3\Lib\site-packages\django\db\backends\base\base.py", line 200, in connect
    self.connection = self.get_new_connection(conn_params)
                      ^^^^^^^^^^^^^^^^^^^^^^^^^^^^^^^^^^^^
  File "C:\Users\ASUS\anaconda3\Lib\site-packages\django\utils\asyncio.py", line 26, in inner
    return func(*args, **kwargs)
           ^^^^^^^^^^^^^^^^^^^^^
  File "C:\Users\ASUS\anaconda3\Lib\site-packages\django\db\backends\mysql\base.py", line 234, in get_new_connection
    connection = Database.connect(**conn_params)
                 ^^^^^^^^^^^^^^^^^^^^^^^^^^^^^^^
  File "C:\Users\ASUS\anaconda3\Lib\site-packages\MySQLdb\__init__.py", line 121, in Connect
    return Connection(*args, **kwargs)
           ^^^^^^^^^^^^^^^^^^^^^^^^^^^
  File "C:\Users\ASUS\anaconda3\Lib\site-packages\MySQLdb\connections.py", line 200, in __init__
    super().__init__(*args, **kwargs2)
django.db.utils.OperationalError: (2002, "Can't connect to server on 'localhost' (10061)")
ERROR 2025-07-09 14:48:06,093 basehttp "GET /api/polyclinics/ HTTP/1.1" 500 226507
ERROR 2025-07-09 14:48:31,092 log Internal Server Error: /doktorlar/
Traceback (most recent call last):
  File "C:\Users\ASUS\anaconda3\Lib\site-packages\django\db\backends\base\base.py", line 219, in ensure_connection
    self.connect()
  File "C:\Users\ASUS\anaconda3\Lib\site-packages\django\utils\asyncio.py", line 26, in inner
    return func(*args, **kwargs)
           ^^^^^^^^^^^^^^^^^^^^^
  File "C:\Users\ASUS\anaconda3\Lib\site-packages\django\db\backends\base\base.py", line 200, in connect
    self.connection = self.get_new_connection(conn_params)
                      ^^^^^^^^^^^^^^^^^^^^^^^^^^^^^^^^^^^^
  File "C:\Users\ASUS\anaconda3\Lib\site-packages\django\utils\asyncio.py", line 26, in inner
    return func(*args, **kwargs)
           ^^^^^^^^^^^^^^^^^^^^^
  File "C:\Users\ASUS\anaconda3\Lib\site-packages\django\db\backends\mysql\base.py", line 234, in get_new_connection
    connection = Database.connect(**conn_params)
                 ^^^^^^^^^^^^^^^^^^^^^^^^^^^^^^^
  File "C:\Users\ASUS\anaconda3\Lib\site-packages\MySQLdb\__init__.py", line 121, in Connect
    return Connection(*args, **kwargs)
           ^^^^^^^^^^^^^^^^^^^^^^^^^^^
  File "C:\Users\ASUS\anaconda3\Lib\site-packages\MySQLdb\connections.py", line 200, in __init__
    super().__init__(*args, **kwargs2)
MySQLdb.OperationalError: (2002, "Can't connect to server on 'localhost' (10061)")

The above exception was the direct cause of the following exception:

Traceback (most recent call last):
  File "C:\Users\ASUS\anaconda3\Lib\site-packages\django\core\handlers\exception.py", line 47, in inner
    response = get_response(request)
               ^^^^^^^^^^^^^^^^^^^^^
  File "C:\Users\ASUS\anaconda3\Lib\site-packages\django\core\handlers\base.py", line 181, in _get_response
    response = wrapped_callback(request, *callback_args, **callback_kwargs)
               ^^^^^^^^^^^^^^^^^^^^^^^^^^^^^^^^^^^^^^^^^^^^^^^^^^^^^^^^^^^^
  File "C:\Users\ASUS\Desktop\HastaneYonetim\HastaneYonetimProjesi\hastane\views\doctor_views.py", line 51, in doctor_list
    return render(request, 'doctors.html', {'doctors': doctors, 'title': 'Doktorlar'})
           ^^^^^^^^^^^^^^^^^^^^^^^^^^^^^^^^^^^^^^^^^^^^^^^^^^^^^^^^^^^^^^^^^^^^^^^^^^^
  File "C:\Users\ASUS\anaconda3\Lib\site-packages\django\shortcuts.py", line 19, in render
    content = loader.render_to_string(template_name, context, request, using=using)
              ^^^^^^^^^^^^^^^^^^^^^^^^^^^^^^^^^^^^^^^^^^^^^^^^^^^^^^^^^^^^^^^^^^^^^
  File "C:\Users\ASUS\anaconda3\Lib\site-packages\django\template\loader.py", line 62, in render_to_string
    return template.render(context, request)
           ^^^^^^^^^^^^^^^^^^^^^^^^^^^^^^^^^
  File "C:\Users\ASUS\anaconda3\Lib\site-packages\django\template\backends\django.py", line 61, in render
    return self.template.render(context)
           ^^^^^^^^^^^^^^^^^^^^^^^^^^^^^
  File "C:\Users\ASUS\anaconda3\Lib\site-packages\django\template\base.py", line 170, in render
    return self._render(context)
           ^^^^^^^^^^^^^^^^^^^^^
  File "C:\Users\ASUS\anaconda3\Lib\site-packages\django\template\base.py", line 162, in _render
    return self.nodelist.render(context)
           ^^^^^^^^^^^^^^^^^^^^^^^^^^^^^
  File "C:\Users\ASUS\anaconda3\Lib\site-packages\django\template\base.py", line 938, in render
    bit = node.render_annotated(context)
          ^^^^^^^^^^^^^^^^^^^^^^^^^^^^^^
  File "C:\Users\ASUS\anaconda3\Lib\site-packages\django\template\base.py", line 905, in render_annotated
    return self.render(context)
           ^^^^^^^^^^^^^^^^^^^^
  File "C:\Users\ASUS\anaconda3\Lib\site-packages\django\template\loader_tags.py", line 150, in render
    return compiled_parent._render(context)
           ^^^^^^^^^^^^^^^^^^^^^^^^^^^^^^^^
  File "C:\Users\ASUS\anaconda3\Lib\site-packages\django\template\base.py", line 162, in _render
    return self.nodelist.render(context)
           ^^^^^^^^^^^^^^^^^^^^^^^^^^^^^
  File "C:\Users\ASUS\anaconda3\Lib\site-packages\django\template\base.py", line 938, in render
    bit = node.render_annotated(context)
          ^^^^^^^^^^^^^^^^^^^^^^^^^^^^^^
  File "C:\Users\ASUS\anaconda3\Lib\site-packages\django\template\base.py", line 905, in render_annotated
    return self.render(context)
           ^^^^^^^^^^^^^^^^^^^^
  File "C:\Users\ASUS\anaconda3\Lib\site-packages\django\template\loader_tags.py", line 62, in render
    result = block.nodelist.render(context)
             ^^^^^^^^^^^^^^^^^^^^^^^^^^^^^^
  File "C:\Users\ASUS\anaconda3\Lib\site-packages\django\template\base.py", line 938, in render
    bit = node.render_annotated(context)
          ^^^^^^^^^^^^^^^^^^^^^^^^^^^^^^
  File "C:\Users\ASUS\anaconda3\Lib\site-packages\django\template\base.py", line 905, in render_annotated
    return self.render(context)
           ^^^^^^^^^^^^^^^^^^^^
  File "C:\Users\ASUS\anaconda3\Lib\site-packages\django\template\defaulttags.py", line 168, in render
    len_values = len(values)
                 ^^^^^^^^^^^
  File "C:\Users\ASUS\anaconda3\Lib\site-packages\django\db\models\query.py", line 262, in __len__
    self._fetch_all()
  File "C:\Users\ASUS\anaconda3\Lib\site-packages\django\db\models\query.py", line 1324, in _fetch_all
    self._result_cache = list(self._iterable_class(self))
                         ^^^^^^^^^^^^^^^^^^^^^^^^^^^^^^^^
  File "C:\Users\ASUS\anaconda3\Lib\site-packages\django\db\models\query.py", line 51, in __iter__
    results = compiler.execute_sql(chunked_fetch=self.chunked_fetch, chunk_size=self.chunk_size)
              ^^^^^^^^^^^^^^^^^^^^^^^^^^^^^^^^^^^^^^^^^^^^^^^^^^^^^^^^^^^^^^^^^^^^^^^^^^^^^^^^^^
  File "C:\Users\ASUS\anaconda3\Lib\site-packages\django\db\models\sql\compiler.py", line 1167, in execute_sql
    cursor = self.connection.cursor()
             ^^^^^^^^^^^^^^^^^^^^^^^^
  File "C:\Users\ASUS\anaconda3\Lib\site-packages\django\utils\asyncio.py", line 26, in inner
    return func(*args, **kwargs)
           ^^^^^^^^^^^^^^^^^^^^^
  File "C:\Users\ASUS\anaconda3\Lib\site-packages\django\db\backends\base\base.py", line 259, in cursor
    return self._cursor()
           ^^^^^^^^^^^^^^
  File "C:\Users\ASUS\anaconda3\Lib\site-packages\django\db\backends\base\base.py", line 235, in _cursor
    self.ensure_connection()
  File "C:\Users\ASUS\anaconda3\Lib\site-packages\django\utils\asyncio.py", line 26, in inner
    return func(*args, **kwargs)
           ^^^^^^^^^^^^^^^^^^^^^
  File "C:\Users\ASUS\anaconda3\Lib\site-packages\django\db\backends\base\base.py", line 218, in ensure_connection
    with self.wrap_database_errors:
  File "C:\Users\ASUS\anaconda3\Lib\site-packages\django\db\utils.py", line 90, in __exit__
    raise dj_exc_value.with_traceback(traceback) from exc_value
  File "C:\Users\ASUS\anaconda3\Lib\site-packages\django\db\backends\base\base.py", line 219, in ensure_connection
    self.connect()
  File "C:\Users\ASUS\anaconda3\Lib\site-packages\django\utils\asyncio.py", line 26, in inner
    return func(*args, **kwargs)
           ^^^^^^^^^^^^^^^^^^^^^
  File "C:\Users\ASUS\anaconda3\Lib\site-packages\django\db\backends\base\base.py", line 200, in connect
    self.connection = self.get_new_connection(conn_params)
                      ^^^^^^^^^^^^^^^^^^^^^^^^^^^^^^^^^^^^
  File "C:\Users\ASUS\anaconda3\Lib\site-packages\django\utils\asyncio.py", line 26, in inner
    return func(*args, **kwargs)
           ^^^^^^^^^^^^^^^^^^^^^
  File "C:\Users\ASUS\anaconda3\Lib\site-packages\django\db\backends\mysql\base.py", line 234, in get_new_connection
    connection = Database.connect(**conn_params)
                 ^^^^^^^^^^^^^^^^^^^^^^^^^^^^^^^
  File "C:\Users\ASUS\anaconda3\Lib\site-packages\MySQLdb\__init__.py", line 121, in Connect
    return Connection(*args, **kwargs)
           ^^^^^^^^^^^^^^^^^^^^^^^^^^^
  File "C:\Users\ASUS\anaconda3\Lib\site-packages\MySQLdb\connections.py", line 200, in __init__
    super().__init__(*args, **kwargs2)
django.db.utils.OperationalError: (2002, "Can't connect to server on 'localhost' (10061)")
ERROR 2025-07-09 14:48:31,227 log Internal Server Error: /doktorlar/
Traceback (most recent call last):
  File "C:\Users\ASUS\anaconda3\Lib\site-packages\django\db\backends\base\base.py", line 219, in ensure_connection
    self.connect()
  File "C:\Users\ASUS\anaconda3\Lib\site-packages\django\utils\asyncio.py", line 26, in inner
    return func(*args, **kwargs)
           ^^^^^^^^^^^^^^^^^^^^^
  File "C:\Users\ASUS\anaconda3\Lib\site-packages\django\db\backends\base\base.py", line 200, in connect
    self.connection = self.get_new_connection(conn_params)
                      ^^^^^^^^^^^^^^^^^^^^^^^^^^^^^^^^^^^^
  File "C:\Users\ASUS\anaconda3\Lib\site-packages\django\utils\asyncio.py", line 26, in inner
    return func(*args, **kwargs)
           ^^^^^^^^^^^^^^^^^^^^^
  File "C:\Users\ASUS\anaconda3\Lib\site-packages\django\db\backends\mysql\base.py", line 234, in get_new_connection
    connection = Database.connect(**conn_params)
                 ^^^^^^^^^^^^^^^^^^^^^^^^^^^^^^^
  File "C:\Users\ASUS\anaconda3\Lib\site-packages\MySQLdb\__init__.py", line 121, in Connect
    return Connection(*args, **kwargs)
           ^^^^^^^^^^^^^^^^^^^^^^^^^^^
  File "C:\Users\ASUS\anaconda3\Lib\site-packages\MySQLdb\connections.py", line 200, in __init__
    super().__init__(*args, **kwargs2)
MySQLdb.OperationalError: (2002, "Can't connect to server on 'localhost' (10061)")

The above exception was the direct cause of the following exception:

Traceback (most recent call last):
  File "C:\Users\ASUS\anaconda3\Lib\site-packages\django\core\handlers\exception.py", line 47, in inner
    response = get_response(request)
               ^^^^^^^^^^^^^^^^^^^^^
  File "C:\Users\ASUS\anaconda3\Lib\site-packages\django\core\handlers\base.py", line 181, in _get_response
    response = wrapped_callback(request, *callback_args, **callback_kwargs)
               ^^^^^^^^^^^^^^^^^^^^^^^^^^^^^^^^^^^^^^^^^^^^^^^^^^^^^^^^^^^^
  File "C:\Users\ASUS\Desktop\HastaneYonetim\HastaneYonetimProjesi\hastane\views\doctor_views.py", line 51, in doctor_list
    return render(request, 'doctors.html', {'doctors': doctors, 'title': 'Doktorlar'})
           ^^^^^^^^^^^^^^^^^^^^^^^^^^^^^^^^^^^^^^^^^^^^^^^^^^^^^^^^^^^^^^^^^^^^^^^^^^^
  File "C:\Users\ASUS\anaconda3\Lib\site-packages\django\shortcuts.py", line 19, in render
    content = loader.render_to_string(template_name, context, request, using=using)
              ^^^^^^^^^^^^^^^^^^^^^^^^^^^^^^^^^^^^^^^^^^^^^^^^^^^^^^^^^^^^^^^^^^^^^
  File "C:\Users\ASUS\anaconda3\Lib\site-packages\django\template\loader.py", line 62, in render_to_string
    return template.render(context, request)
           ^^^^^^^^^^^^^^^^^^^^^^^^^^^^^^^^^
  File "C:\Users\ASUS\anaconda3\Lib\site-packages\django\template\backends\django.py", line 61, in render
    return self.template.render(context)
           ^^^^^^^^^^^^^^^^^^^^^^^^^^^^^
  File "C:\Users\ASUS\anaconda3\Lib\site-packages\django\template\base.py", line 170, in render
    return self._render(context)
           ^^^^^^^^^^^^^^^^^^^^^
  File "C:\Users\ASUS\anaconda3\Lib\site-packages\django\template\base.py", line 162, in _render
    return self.nodelist.render(context)
           ^^^^^^^^^^^^^^^^^^^^^^^^^^^^^
  File "C:\Users\ASUS\anaconda3\Lib\site-packages\django\template\base.py", line 938, in render
    bit = node.render_annotated(context)
          ^^^^^^^^^^^^^^^^^^^^^^^^^^^^^^
  File "C:\Users\ASUS\anaconda3\Lib\site-packages\django\template\base.py", line 905, in render_annotated
    return self.render(context)
           ^^^^^^^^^^^^^^^^^^^^
  File "C:\Users\ASUS\anaconda3\Lib\site-packages\django\template\loader_tags.py", line 150, in render
    return compiled_parent._render(context)
           ^^^^^^^^^^^^^^^^^^^^^^^^^^^^^^^^
  File "C:\Users\ASUS\anaconda3\Lib\site-packages\django\template\base.py", line 162, in _render
    return self.nodelist.render(context)
           ^^^^^^^^^^^^^^^^^^^^^^^^^^^^^
  File "C:\Users\ASUS\anaconda3\Lib\site-packages\django\template\base.py", line 938, in render
    bit = node.render_annotated(context)
          ^^^^^^^^^^^^^^^^^^^^^^^^^^^^^^
  File "C:\Users\ASUS\anaconda3\Lib\site-packages\django\template\base.py", line 905, in render_annotated
    return self.render(context)
           ^^^^^^^^^^^^^^^^^^^^
  File "C:\Users\ASUS\anaconda3\Lib\site-packages\django\template\loader_tags.py", line 62, in render
    result = block.nodelist.render(context)
             ^^^^^^^^^^^^^^^^^^^^^^^^^^^^^^
  File "C:\Users\ASUS\anaconda3\Lib\site-packages\django\template\base.py", line 938, in render
    bit = node.render_annotated(context)
          ^^^^^^^^^^^^^^^^^^^^^^^^^^^^^^
  File "C:\Users\ASUS\anaconda3\Lib\site-packages\django\template\base.py", line 905, in render_annotated
    return self.render(context)
           ^^^^^^^^^^^^^^^^^^^^
  File "C:\Users\ASUS\anaconda3\Lib\site-packages\django\template\defaulttags.py", line 168, in render
    len_values = len(values)
                 ^^^^^^^^^^^
  File "C:\Users\ASUS\anaconda3\Lib\site-packages\django\db\models\query.py", line 262, in __len__
    self._fetch_all()
  File "C:\Users\ASUS\anaconda3\Lib\site-packages\django\db\models\query.py", line 1324, in _fetch_all
    self._result_cache = list(self._iterable_class(self))
                         ^^^^^^^^^^^^^^^^^^^^^^^^^^^^^^^^
  File "C:\Users\ASUS\anaconda3\Lib\site-packages\django\db\models\query.py", line 51, in __iter__
    results = compiler.execute_sql(chunked_fetch=self.chunked_fetch, chunk_size=self.chunk_size)
              ^^^^^^^^^^^^^^^^^^^^^^^^^^^^^^^^^^^^^^^^^^^^^^^^^^^^^^^^^^^^^^^^^^^^^^^^^^^^^^^^^^
  File "C:\Users\ASUS\anaconda3\Lib\site-packages\django\db\models\sql\compiler.py", line 1167, in execute_sql
    cursor = self.connection.cursor()
             ^^^^^^^^^^^^^^^^^^^^^^^^
  File "C:\Users\ASUS\anaconda3\Lib\site-packages\django\utils\asyncio.py", line 26, in inner
    return func(*args, **kwargs)
           ^^^^^^^^^^^^^^^^^^^^^
  File "C:\Users\ASUS\anaconda3\Lib\site-packages\django\db\backends\base\base.py", line 259, in cursor
    return self._cursor()
           ^^^^^^^^^^^^^^
  File "C:\Users\ASUS\anaconda3\Lib\site-packages\django\db\backends\base\base.py", line 235, in _cursor
    self.ensure_connection()
  File "C:\Users\ASUS\anaconda3\Lib\site-packages\django\utils\asyncio.py", line 26, in inner
    return func(*args, **kwargs)
           ^^^^^^^^^^^^^^^^^^^^^
  File "C:\Users\ASUS\anaconda3\Lib\site-packages\django\db\backends\base\base.py", line 218, in ensure_connection
    with self.wrap_database_errors:
  File "C:\Users\ASUS\anaconda3\Lib\site-packages\django\db\utils.py", line 90, in __exit__
    raise dj_exc_value.with_traceback(traceback) from exc_value
  File "C:\Users\ASUS\anaconda3\Lib\site-packages\django\db\backends\base\base.py", line 219, in ensure_connection
    self.connect()
  File "C:\Users\ASUS\anaconda3\Lib\site-packages\django\utils\asyncio.py", line 26, in inner
    return func(*args, **kwargs)
           ^^^^^^^^^^^^^^^^^^^^^
  File "C:\Users\ASUS\anaconda3\Lib\site-packages\django\db\backends\base\base.py", line 200, in connect
    self.connection = self.get_new_connection(conn_params)
                      ^^^^^^^^^^^^^^^^^^^^^^^^^^^^^^^^^^^^
  File "C:\Users\ASUS\anaconda3\Lib\site-packages\django\utils\asyncio.py", line 26, in inner
    return func(*args, **kwargs)
           ^^^^^^^^^^^^^^^^^^^^^
  File "C:\Users\ASUS\anaconda3\Lib\site-packages\django\db\backends\mysql\base.py", line 234, in get_new_connection
    connection = Database.connect(**conn_params)
                 ^^^^^^^^^^^^^^^^^^^^^^^^^^^^^^^
  File "C:\Users\ASUS\anaconda3\Lib\site-packages\MySQLdb\__init__.py", line 121, in Connect
    return Connection(*args, **kwargs)
           ^^^^^^^^^^^^^^^^^^^^^^^^^^^
  File "C:\Users\ASUS\anaconda3\Lib\site-packages\MySQLdb\connections.py", line 200, in __init__
    super().__init__(*args, **kwargs2)
django.db.utils.OperationalError: (2002, "Can't connect to server on 'localhost' (10061)")
ERROR 2025-07-09 14:48:31,342 log Internal Server Error: /doktorlar/
Traceback (most recent call last):
  File "C:\Users\ASUS\anaconda3\Lib\site-packages\django\db\backends\base\base.py", line 219, in ensure_connection
    self.connect()
  File "C:\Users\ASUS\anaconda3\Lib\site-packages\django\utils\asyncio.py", line 26, in inner
    return func(*args, **kwargs)
           ^^^^^^^^^^^^^^^^^^^^^
  File "C:\Users\ASUS\anaconda3\Lib\site-packages\django\db\backends\base\base.py", line 200, in connect
    self.connection = self.get_new_connection(conn_params)
                      ^^^^^^^^^^^^^^^^^^^^^^^^^^^^^^^^^^^^
  File "C:\Users\ASUS\anaconda3\Lib\site-packages\django\utils\asyncio.py", line 26, in inner
    return func(*args, **kwargs)
           ^^^^^^^^^^^^^^^^^^^^^
  File "C:\Users\ASUS\anaconda3\Lib\site-packages\django\db\backends\mysql\base.py", line 234, in get_new_connection
    connection = Database.connect(**conn_params)
                 ^^^^^^^^^^^^^^^^^^^^^^^^^^^^^^^
  File "C:\Users\ASUS\anaconda3\Lib\site-packages\MySQLdb\__init__.py", line 121, in Connect
    return Connection(*args, **kwargs)
           ^^^^^^^^^^^^^^^^^^^^^^^^^^^
  File "C:\Users\ASUS\anaconda3\Lib\site-packages\MySQLdb\connections.py", line 200, in __init__
    super().__init__(*args, **kwargs2)
MySQLdb.OperationalError: (2002, "Can't connect to server on 'localhost' (10061)")

The above exception was the direct cause of the following exception:

Traceback (most recent call last):
  File "C:\Users\ASUS\anaconda3\Lib\site-packages\django\core\handlers\exception.py", line 47, in inner
    response = get_response(request)
               ^^^^^^^^^^^^^^^^^^^^^
  File "C:\Users\ASUS\anaconda3\Lib\site-packages\django\core\handlers\base.py", line 181, in _get_response
    response = wrapped_callback(request, *callback_args, **callback_kwargs)
               ^^^^^^^^^^^^^^^^^^^^^^^^^^^^^^^^^^^^^^^^^^^^^^^^^^^^^^^^^^^^
  File "C:\Users\ASUS\Desktop\HastaneYonetim\HastaneYonetimProjesi\hastane\views\doctor_views.py", line 51, in doctor_list
    return render(request, 'doctors.html', {'doctors': doctors, 'title': 'Doktorlar'})
           ^^^^^^^^^^^^^^^^^^^^^^^^^^^^^^^^^^^^^^^^^^^^^^^^^^^^^^^^^^^^^^^^^^^^^^^^^^^
  File "C:\Users\ASUS\anaconda3\Lib\site-packages\django\shortcuts.py", line 19, in render
    content = loader.render_to_string(template_name, context, request, using=using)
              ^^^^^^^^^^^^^^^^^^^^^^^^^^^^^^^^^^^^^^^^^^^^^^^^^^^^^^^^^^^^^^^^^^^^^
  File "C:\Users\ASUS\anaconda3\Lib\site-packages\django\template\loader.py", line 62, in render_to_string
    return template.render(context, request)
           ^^^^^^^^^^^^^^^^^^^^^^^^^^^^^^^^^
  File "C:\Users\ASUS\anaconda3\Lib\site-packages\django\template\backends\django.py", line 61, in render
    return self.template.render(context)
           ^^^^^^^^^^^^^^^^^^^^^^^^^^^^^
  File "C:\Users\ASUS\anaconda3\Lib\site-packages\django\template\base.py", line 170, in render
    return self._render(context)
           ^^^^^^^^^^^^^^^^^^^^^
  File "C:\Users\ASUS\anaconda3\Lib\site-packages\django\template\base.py", line 162, in _render
    return self.nodelist.render(context)
           ^^^^^^^^^^^^^^^^^^^^^^^^^^^^^
  File "C:\Users\ASUS\anaconda3\Lib\site-packages\django\template\base.py", line 938, in render
    bit = node.render_annotated(context)
          ^^^^^^^^^^^^^^^^^^^^^^^^^^^^^^
  File "C:\Users\ASUS\anaconda3\Lib\site-packages\django\template\base.py", line 905, in render_annotated
    return self.render(context)
           ^^^^^^^^^^^^^^^^^^^^
  File "C:\Users\ASUS\anaconda3\Lib\site-packages\django\template\loader_tags.py", line 150, in render
    return compiled_parent._render(context)
           ^^^^^^^^^^^^^^^^^^^^^^^^^^^^^^^^
  File "C:\Users\ASUS\anaconda3\Lib\site-packages\django\template\base.py", line 162, in _render
    return self.nodelist.render(context)
           ^^^^^^^^^^^^^^^^^^^^^^^^^^^^^
  File "C:\Users\ASUS\anaconda3\Lib\site-packages\django\template\base.py", line 938, in render
    bit = node.render_annotated(context)
          ^^^^^^^^^^^^^^^^^^^^^^^^^^^^^^
  File "C:\Users\ASUS\anaconda3\Lib\site-packages\django\template\base.py", line 905, in render_annotated
    return self.render(context)
           ^^^^^^^^^^^^^^^^^^^^
  File "C:\Users\ASUS\anaconda3\Lib\site-packages\django\template\loader_tags.py", line 62, in render
    result = block.nodelist.render(context)
             ^^^^^^^^^^^^^^^^^^^^^^^^^^^^^^
  File "C:\Users\ASUS\anaconda3\Lib\site-packages\django\template\base.py", line 938, in render
    bit = node.render_annotated(context)
          ^^^^^^^^^^^^^^^^^^^^^^^^^^^^^^
  File "C:\Users\ASUS\anaconda3\Lib\site-packages\django\template\base.py", line 905, in render_annotated
    return self.render(context)
           ^^^^^^^^^^^^^^^^^^^^
  File "C:\Users\ASUS\anaconda3\Lib\site-packages\django\template\defaulttags.py", line 168, in render
    len_values = len(values)
                 ^^^^^^^^^^^
  File "C:\Users\ASUS\anaconda3\Lib\site-packages\django\db\models\query.py", line 262, in __len__
    self._fetch_all()
  File "C:\Users\ASUS\anaconda3\Lib\site-packages\django\db\models\query.py", line 1324, in _fetch_all
    self._result_cache = list(self._iterable_class(self))
                         ^^^^^^^^^^^^^^^^^^^^^^^^^^^^^^^^
  File "C:\Users\ASUS\anaconda3\Lib\site-packages\django\db\models\query.py", line 51, in __iter__
    results = compiler.execute_sql(chunked_fetch=self.chunked_fetch, chunk_size=self.chunk_size)
              ^^^^^^^^^^^^^^^^^^^^^^^^^^^^^^^^^^^^^^^^^^^^^^^^^^^^^^^^^^^^^^^^^^^^^^^^^^^^^^^^^^
  File "C:\Users\ASUS\anaconda3\Lib\site-packages\django\db\models\sql\compiler.py", line 1167, in execute_sql
    cursor = self.connection.cursor()
             ^^^^^^^^^^^^^^^^^^^^^^^^
  File "C:\Users\ASUS\anaconda3\Lib\site-packages\django\utils\asyncio.py", line 26, in inner
    return func(*args, **kwargs)
           ^^^^^^^^^^^^^^^^^^^^^
  File "C:\Users\ASUS\anaconda3\Lib\site-packages\django\db\backends\base\base.py", line 259, in cursor
    return self._cursor()
           ^^^^^^^^^^^^^^
  File "C:\Users\ASUS\anaconda3\Lib\site-packages\django\db\backends\base\base.py", line 235, in _cursor
    self.ensure_connection()
  File "C:\Users\ASUS\anaconda3\Lib\site-packages\django\utils\asyncio.py", line 26, in inner
    return func(*args, **kwargs)
           ^^^^^^^^^^^^^^^^^^^^^
  File "C:\Users\ASUS\anaconda3\Lib\site-packages\django\db\backends\base\base.py", line 218, in ensure_connection
    with self.wrap_database_errors:
  File "C:\Users\ASUS\anaconda3\Lib\site-packages\django\db\utils.py", line 90, in __exit__
    raise dj_exc_value.with_traceback(traceback) from exc_value
  File "C:\Users\ASUS\anaconda3\Lib\site-packages\django\db\backends\base\base.py", line 219, in ensure_connection
    self.connect()
  File "C:\Users\ASUS\anaconda3\Lib\site-packages\django\utils\asyncio.py", line 26, in inner
    return func(*args, **kwargs)
           ^^^^^^^^^^^^^^^^^^^^^
  File "C:\Users\ASUS\anaconda3\Lib\site-packages\django\db\backends\base\base.py", line 200, in connect
    self.connection = self.get_new_connection(conn_params)
                      ^^^^^^^^^^^^^^^^^^^^^^^^^^^^^^^^^^^^
  File "C:\Users\ASUS\anaconda3\Lib\site-packages\django\utils\asyncio.py", line 26, in inner
    return func(*args, **kwargs)
           ^^^^^^^^^^^^^^^^^^^^^
  File "C:\Users\ASUS\anaconda3\Lib\site-packages\django\db\backends\mysql\base.py", line 234, in get_new_connection
    connection = Database.connect(**conn_params)
                 ^^^^^^^^^^^^^^^^^^^^^^^^^^^^^^^
  File "C:\Users\ASUS\anaconda3\Lib\site-packages\MySQLdb\__init__.py", line 121, in Connect
    return Connection(*args, **kwargs)
           ^^^^^^^^^^^^^^^^^^^^^^^^^^^
  File "C:\Users\ASUS\anaconda3\Lib\site-packages\MySQLdb\connections.py", line 200, in __init__
    super().__init__(*args, **kwargs2)
django.db.utils.OperationalError: (2002, "Can't connect to server on 'localhost' (10061)")
ERROR 2025-07-09 14:48:31,349 log Internal Server Error: /doktorlar/
Traceback (most recent call last):
  File "C:\Users\ASUS\anaconda3\Lib\site-packages\django\db\backends\base\base.py", line 219, in ensure_connection
    self.connect()
  File "C:\Users\ASUS\anaconda3\Lib\site-packages\django\utils\asyncio.py", line 26, in inner
    return func(*args, **kwargs)
           ^^^^^^^^^^^^^^^^^^^^^
  File "C:\Users\ASUS\anaconda3\Lib\site-packages\django\db\backends\base\base.py", line 200, in connect
    self.connection = self.get_new_connection(conn_params)
                      ^^^^^^^^^^^^^^^^^^^^^^^^^^^^^^^^^^^^
  File "C:\Users\ASUS\anaconda3\Lib\site-packages\django\utils\asyncio.py", line 26, in inner
    return func(*args, **kwargs)
           ^^^^^^^^^^^^^^^^^^^^^
  File "C:\Users\ASUS\anaconda3\Lib\site-packages\django\db\backends\mysql\base.py", line 234, in get_new_connection
    connection = Database.connect(**conn_params)
                 ^^^^^^^^^^^^^^^^^^^^^^^^^^^^^^^
  File "C:\Users\ASUS\anaconda3\Lib\site-packages\MySQLdb\__init__.py", line 121, in Connect
    return Connection(*args, **kwargs)
           ^^^^^^^^^^^^^^^^^^^^^^^^^^^
  File "C:\Users\ASUS\anaconda3\Lib\site-packages\MySQLdb\connections.py", line 200, in __init__
    super().__init__(*args, **kwargs2)
MySQLdb.OperationalError: (2002, "Can't connect to server on 'localhost' (10061)")

The above exception was the direct cause of the following exception:

Traceback (most recent call last):
  File "C:\Users\ASUS\anaconda3\Lib\site-packages\django\core\handlers\exception.py", line 47, in inner
    response = get_response(request)
               ^^^^^^^^^^^^^^^^^^^^^
  File "C:\Users\ASUS\anaconda3\Lib\site-packages\django\core\handlers\base.py", line 181, in _get_response
    response = wrapped_callback(request, *callback_args, **callback_kwargs)
               ^^^^^^^^^^^^^^^^^^^^^^^^^^^^^^^^^^^^^^^^^^^^^^^^^^^^^^^^^^^^
  File "C:\Users\ASUS\Desktop\HastaneYonetim\HastaneYonetimProjesi\hastane\views\doctor_views.py", line 51, in doctor_list
    return render(request, 'doctors.html', {'doctors': doctors, 'title': 'Doktorlar'})
           ^^^^^^^^^^^^^^^^^^^^^^^^^^^^^^^^^^^^^^^^^^^^^^^^^^^^^^^^^^^^^^^^^^^^^^^^^^^
  File "C:\Users\ASUS\anaconda3\Lib\site-packages\django\shortcuts.py", line 19, in render
    content = loader.render_to_string(template_name, context, request, using=using)
              ^^^^^^^^^^^^^^^^^^^^^^^^^^^^^^^^^^^^^^^^^^^^^^^^^^^^^^^^^^^^^^^^^^^^^
  File "C:\Users\ASUS\anaconda3\Lib\site-packages\django\template\loader.py", line 62, in render_to_string
    return template.render(context, request)
           ^^^^^^^^^^^^^^^^^^^^^^^^^^^^^^^^^
  File "C:\Users\ASUS\anaconda3\Lib\site-packages\django\template\backends\django.py", line 61, in render
    return self.template.render(context)
           ^^^^^^^^^^^^^^^^^^^^^^^^^^^^^
  File "C:\Users\ASUS\anaconda3\Lib\site-packages\django\template\base.py", line 170, in render
    return self._render(context)
           ^^^^^^^^^^^^^^^^^^^^^
  File "C:\Users\ASUS\anaconda3\Lib\site-packages\django\template\base.py", line 162, in _render
    return self.nodelist.render(context)
           ^^^^^^^^^^^^^^^^^^^^^^^^^^^^^
  File "C:\Users\ASUS\anaconda3\Lib\site-packages\django\template\base.py", line 938, in render
    bit = node.render_annotated(context)
          ^^^^^^^^^^^^^^^^^^^^^^^^^^^^^^
  File "C:\Users\ASUS\anaconda3\Lib\site-packages\django\template\base.py", line 905, in render_annotated
    return self.render(context)
           ^^^^^^^^^^^^^^^^^^^^
  File "C:\Users\ASUS\anaconda3\Lib\site-packages\django\template\loader_tags.py", line 150, in render
    return compiled_parent._render(context)
           ^^^^^^^^^^^^^^^^^^^^^^^^^^^^^^^^
  File "C:\Users\ASUS\anaconda3\Lib\site-packages\django\template\base.py", line 162, in _render
    return self.nodelist.render(context)
           ^^^^^^^^^^^^^^^^^^^^^^^^^^^^^
  File "C:\Users\ASUS\anaconda3\Lib\site-packages\django\template\base.py", line 938, in render
    bit = node.render_annotated(context)
          ^^^^^^^^^^^^^^^^^^^^^^^^^^^^^^
  File "C:\Users\ASUS\anaconda3\Lib\site-packages\django\template\base.py", line 905, in render_annotated
    return self.render(context)
           ^^^^^^^^^^^^^^^^^^^^
  File "C:\Users\ASUS\anaconda3\Lib\site-packages\django\template\loader_tags.py", line 62, in render
    result = block.nodelist.render(context)
             ^^^^^^^^^^^^^^^^^^^^^^^^^^^^^^
  File "C:\Users\ASUS\anaconda3\Lib\site-packages\django\template\base.py", line 938, in render
    bit = node.render_annotated(context)
          ^^^^^^^^^^^^^^^^^^^^^^^^^^^^^^
  File "C:\Users\ASUS\anaconda3\Lib\site-packages\django\template\base.py", line 905, in render_annotated
    return self.render(context)
           ^^^^^^^^^^^^^^^^^^^^
  File "C:\Users\ASUS\anaconda3\Lib\site-packages\django\template\defaulttags.py", line 168, in render
    len_values = len(values)
                 ^^^^^^^^^^^
  File "C:\Users\ASUS\anaconda3\Lib\site-packages\django\db\models\query.py", line 262, in __len__
    self._fetch_all()
  File "C:\Users\ASUS\anaconda3\Lib\site-packages\django\db\models\query.py", line 1324, in _fetch_all
    self._result_cache = list(self._iterable_class(self))
                         ^^^^^^^^^^^^^^^^^^^^^^^^^^^^^^^^
  File "C:\Users\ASUS\anaconda3\Lib\site-packages\django\db\models\query.py", line 51, in __iter__
    results = compiler.execute_sql(chunked_fetch=self.chunked_fetch, chunk_size=self.chunk_size)
              ^^^^^^^^^^^^^^^^^^^^^^^^^^^^^^^^^^^^^^^^^^^^^^^^^^^^^^^^^^^^^^^^^^^^^^^^^^^^^^^^^^
  File "C:\Users\ASUS\anaconda3\Lib\site-packages\django\db\models\sql\compiler.py", line 1167, in execute_sql
    cursor = self.connection.cursor()
             ^^^^^^^^^^^^^^^^^^^^^^^^
  File "C:\Users\ASUS\anaconda3\Lib\site-packages\django\utils\asyncio.py", line 26, in inner
    return func(*args, **kwargs)
           ^^^^^^^^^^^^^^^^^^^^^
  File "C:\Users\ASUS\anaconda3\Lib\site-packages\django\db\backends\base\base.py", line 259, in cursor
    return self._cursor()
           ^^^^^^^^^^^^^^
  File "C:\Users\ASUS\anaconda3\Lib\site-packages\django\db\backends\base\base.py", line 235, in _cursor
    self.ensure_connection()
  File "C:\Users\ASUS\anaconda3\Lib\site-packages\django\utils\asyncio.py", line 26, in inner
    return func(*args, **kwargs)
           ^^^^^^^^^^^^^^^^^^^^^
  File "C:\Users\ASUS\anaconda3\Lib\site-packages\django\db\backends\base\base.py", line 218, in ensure_connection
    with self.wrap_database_errors:
  File "C:\Users\ASUS\anaconda3\Lib\site-packages\django\db\utils.py", line 90, in __exit__
    raise dj_exc_value.with_traceback(traceback) from exc_value
  File "C:\Users\ASUS\anaconda3\Lib\site-packages\django\db\backends\base\base.py", line 219, in ensure_connection
    self.connect()
  File "C:\Users\ASUS\anaconda3\Lib\site-packages\django\utils\asyncio.py", line 26, in inner
    return func(*args, **kwargs)
           ^^^^^^^^^^^^^^^^^^^^^
  File "C:\Users\ASUS\anaconda3\Lib\site-packages\django\db\backends\base\base.py", line 200, in connect
    self.connection = self.get_new_connection(conn_params)
                      ^^^^^^^^^^^^^^^^^^^^^^^^^^^^^^^^^^^^
  File "C:\Users\ASUS\anaconda3\Lib\site-packages\django\utils\asyncio.py", line 26, in inner
    return func(*args, **kwargs)
           ^^^^^^^^^^^^^^^^^^^^^
  File "C:\Users\ASUS\anaconda3\Lib\site-packages\django\db\backends\mysql\base.py", line 234, in get_new_connection
    connection = Database.connect(**conn_params)
                 ^^^^^^^^^^^^^^^^^^^^^^^^^^^^^^^
  File "C:\Users\ASUS\anaconda3\Lib\site-packages\MySQLdb\__init__.py", line 121, in Connect
    return Connection(*args, **kwargs)
           ^^^^^^^^^^^^^^^^^^^^^^^^^^^
  File "C:\Users\ASUS\anaconda3\Lib\site-packages\MySQLdb\connections.py", line 200, in __init__
    super().__init__(*args, **kwargs2)
django.db.utils.OperationalError: (2002, "Can't connect to server on 'localhost' (10061)")
ERROR 2025-07-09 14:48:31,436 log Internal Server Error: /doktorlar/
Traceback (most recent call last):
  File "C:\Users\ASUS\anaconda3\Lib\site-packages\django\db\backends\base\base.py", line 219, in ensure_connection
    self.connect()
  File "C:\Users\ASUS\anaconda3\Lib\site-packages\django\utils\asyncio.py", line 26, in inner
    return func(*args, **kwargs)
           ^^^^^^^^^^^^^^^^^^^^^
  File "C:\Users\ASUS\anaconda3\Lib\site-packages\django\db\backends\base\base.py", line 200, in connect
    self.connection = self.get_new_connection(conn_params)
                      ^^^^^^^^^^^^^^^^^^^^^^^^^^^^^^^^^^^^
  File "C:\Users\ASUS\anaconda3\Lib\site-packages\django\utils\asyncio.py", line 26, in inner
    return func(*args, **kwargs)
           ^^^^^^^^^^^^^^^^^^^^^
  File "C:\Users\ASUS\anaconda3\Lib\site-packages\django\db\backends\mysql\base.py", line 234, in get_new_connection
    connection = Database.connect(**conn_params)
                 ^^^^^^^^^^^^^^^^^^^^^^^^^^^^^^^
  File "C:\Users\ASUS\anaconda3\Lib\site-packages\MySQLdb\__init__.py", line 121, in Connect
    return Connection(*args, **kwargs)
           ^^^^^^^^^^^^^^^^^^^^^^^^^^^
  File "C:\Users\ASUS\anaconda3\Lib\site-packages\MySQLdb\connections.py", line 200, in __init__
    super().__init__(*args, **kwargs2)
MySQLdb.OperationalError: (2002, "Can't connect to server on 'localhost' (10061)")

The above exception was the direct cause of the following exception:

Traceback (most recent call last):
  File "C:\Users\ASUS\anaconda3\Lib\site-packages\django\core\handlers\exception.py", line 47, in inner
    response = get_response(request)
               ^^^^^^^^^^^^^^^^^^^^^
  File "C:\Users\ASUS\anaconda3\Lib\site-packages\django\core\handlers\base.py", line 181, in _get_response
    response = wrapped_callback(request, *callback_args, **callback_kwargs)
               ^^^^^^^^^^^^^^^^^^^^^^^^^^^^^^^^^^^^^^^^^^^^^^^^^^^^^^^^^^^^
  File "C:\Users\ASUS\Desktop\HastaneYonetim\HastaneYonetimProjesi\hastane\views\doctor_views.py", line 51, in doctor_list
    return render(request, 'doctors.html', {'doctors': doctors, 'title': 'Doktorlar'})
           ^^^^^^^^^^^^^^^^^^^^^^^^^^^^^^^^^^^^^^^^^^^^^^^^^^^^^^^^^^^^^^^^^^^^^^^^^^^
  File "C:\Users\ASUS\anaconda3\Lib\site-packages\django\shortcuts.py", line 19, in render
    content = loader.render_to_string(template_name, context, request, using=using)
              ^^^^^^^^^^^^^^^^^^^^^^^^^^^^^^^^^^^^^^^^^^^^^^^^^^^^^^^^^^^^^^^^^^^^^
  File "C:\Users\ASUS\anaconda3\Lib\site-packages\django\template\loader.py", line 62, in render_to_string
    return template.render(context, request)
           ^^^^^^^^^^^^^^^^^^^^^^^^^^^^^^^^^
  File "C:\Users\ASUS\anaconda3\Lib\site-packages\django\template\backends\django.py", line 61, in render
    return self.template.render(context)
           ^^^^^^^^^^^^^^^^^^^^^^^^^^^^^
  File "C:\Users\ASUS\anaconda3\Lib\site-packages\django\template\base.py", line 170, in render
    return self._render(context)
           ^^^^^^^^^^^^^^^^^^^^^
  File "C:\Users\ASUS\anaconda3\Lib\site-packages\django\template\base.py", line 162, in _render
    return self.nodelist.render(context)
           ^^^^^^^^^^^^^^^^^^^^^^^^^^^^^
  File "C:\Users\ASUS\anaconda3\Lib\site-packages\django\template\base.py", line 938, in render
    bit = node.render_annotated(context)
          ^^^^^^^^^^^^^^^^^^^^^^^^^^^^^^
  File "C:\Users\ASUS\anaconda3\Lib\site-packages\django\template\base.py", line 905, in render_annotated
    return self.render(context)
           ^^^^^^^^^^^^^^^^^^^^
  File "C:\Users\ASUS\anaconda3\Lib\site-packages\django\template\loader_tags.py", line 150, in render
    return compiled_parent._render(context)
           ^^^^^^^^^^^^^^^^^^^^^^^^^^^^^^^^
  File "C:\Users\ASUS\anaconda3\Lib\site-packages\django\template\base.py", line 162, in _render
    return self.nodelist.render(context)
           ^^^^^^^^^^^^^^^^^^^^^^^^^^^^^
  File "C:\Users\ASUS\anaconda3\Lib\site-packages\django\template\base.py", line 938, in render
    bit = node.render_annotated(context)
          ^^^^^^^^^^^^^^^^^^^^^^^^^^^^^^
  File "C:\Users\ASUS\anaconda3\Lib\site-packages\django\template\base.py", line 905, in render_annotated
    return self.render(context)
           ^^^^^^^^^^^^^^^^^^^^
  File "C:\Users\ASUS\anaconda3\Lib\site-packages\django\template\loader_tags.py", line 62, in render
    result = block.nodelist.render(context)
             ^^^^^^^^^^^^^^^^^^^^^^^^^^^^^^
  File "C:\Users\ASUS\anaconda3\Lib\site-packages\django\template\base.py", line 938, in render
    bit = node.render_annotated(context)
          ^^^^^^^^^^^^^^^^^^^^^^^^^^^^^^
  File "C:\Users\ASUS\anaconda3\Lib\site-packages\django\template\base.py", line 905, in render_annotated
    return self.render(context)
           ^^^^^^^^^^^^^^^^^^^^
  File "C:\Users\ASUS\anaconda3\Lib\site-packages\django\template\defaulttags.py", line 168, in render
    len_values = len(values)
                 ^^^^^^^^^^^
  File "C:\Users\ASUS\anaconda3\Lib\site-packages\django\db\models\query.py", line 262, in __len__
    self._fetch_all()
  File "C:\Users\ASUS\anaconda3\Lib\site-packages\django\db\models\query.py", line 1324, in _fetch_all
    self._result_cache = list(self._iterable_class(self))
                         ^^^^^^^^^^^^^^^^^^^^^^^^^^^^^^^^
  File "C:\Users\ASUS\anaconda3\Lib\site-packages\django\db\models\query.py", line 51, in __iter__
    results = compiler.execute_sql(chunked_fetch=self.chunked_fetch, chunk_size=self.chunk_size)
              ^^^^^^^^^^^^^^^^^^^^^^^^^^^^^^^^^^^^^^^^^^^^^^^^^^^^^^^^^^^^^^^^^^^^^^^^^^^^^^^^^^
  File "C:\Users\ASUS\anaconda3\Lib\site-packages\django\db\models\sql\compiler.py", line 1167, in execute_sql
    cursor = self.connection.cursor()
             ^^^^^^^^^^^^^^^^^^^^^^^^
  File "C:\Users\ASUS\anaconda3\Lib\site-packages\django\utils\asyncio.py", line 26, in inner
    return func(*args, **kwargs)
           ^^^^^^^^^^^^^^^^^^^^^
  File "C:\Users\ASUS\anaconda3\Lib\site-packages\django\db\backends\base\base.py", line 259, in cursor
    return self._cursor()
           ^^^^^^^^^^^^^^
  File "C:\Users\ASUS\anaconda3\Lib\site-packages\django\db\backends\base\base.py", line 235, in _cursor
    self.ensure_connection()
  File "C:\Users\ASUS\anaconda3\Lib\site-packages\django\utils\asyncio.py", line 26, in inner
    return func(*args, **kwargs)
           ^^^^^^^^^^^^^^^^^^^^^
  File "C:\Users\ASUS\anaconda3\Lib\site-packages\django\db\backends\base\base.py", line 218, in ensure_connection
    with self.wrap_database_errors:
  File "C:\Users\ASUS\anaconda3\Lib\site-packages\django\db\utils.py", line 90, in __exit__
    raise dj_exc_value.with_traceback(traceback) from exc_value
  File "C:\Users\ASUS\anaconda3\Lib\site-packages\django\db\backends\base\base.py", line 219, in ensure_connection
    self.connect()
  File "C:\Users\ASUS\anaconda3\Lib\site-packages\django\utils\asyncio.py", line 26, in inner
    return func(*args, **kwargs)
           ^^^^^^^^^^^^^^^^^^^^^
  File "C:\Users\ASUS\anaconda3\Lib\site-packages\django\db\backends\base\base.py", line 200, in connect
    self.connection = self.get_new_connection(conn_params)
                      ^^^^^^^^^^^^^^^^^^^^^^^^^^^^^^^^^^^^
  File "C:\Users\ASUS\anaconda3\Lib\site-packages\django\utils\asyncio.py", line 26, in inner
    return func(*args, **kwargs)
           ^^^^^^^^^^^^^^^^^^^^^
  File "C:\Users\ASUS\anaconda3\Lib\site-packages\django\db\backends\mysql\base.py", line 234, in get_new_connection
    connection = Database.connect(**conn_params)
                 ^^^^^^^^^^^^^^^^^^^^^^^^^^^^^^^
  File "C:\Users\ASUS\anaconda3\Lib\site-packages\MySQLdb\__init__.py", line 121, in Connect
    return Connection(*args, **kwargs)
           ^^^^^^^^^^^^^^^^^^^^^^^^^^^
  File "C:\Users\ASUS\anaconda3\Lib\site-packages\MySQLdb\connections.py", line 200, in __init__
    super().__init__(*args, **kwargs2)
django.db.utils.OperationalError: (2002, "Can't connect to server on 'localhost' (10061)")
ERROR 2025-07-09 14:48:31,455 basehttp "GET /doktorlar/ HTTP/1.1" 500 300039
ERROR 2025-07-09 14:48:31,518 log Internal Server Error: /doktorlar/
Traceback (most recent call last):
  File "C:\Users\ASUS\anaconda3\Lib\site-packages\django\db\backends\base\base.py", line 219, in ensure_connection
    self.connect()
  File "C:\Users\ASUS\anaconda3\Lib\site-packages\django\utils\asyncio.py", line 26, in inner
    return func(*args, **kwargs)
           ^^^^^^^^^^^^^^^^^^^^^
  File "C:\Users\ASUS\anaconda3\Lib\site-packages\django\db\backends\base\base.py", line 200, in connect
    self.connection = self.get_new_connection(conn_params)
                      ^^^^^^^^^^^^^^^^^^^^^^^^^^^^^^^^^^^^
  File "C:\Users\ASUS\anaconda3\Lib\site-packages\django\utils\asyncio.py", line 26, in inner
    return func(*args, **kwargs)
           ^^^^^^^^^^^^^^^^^^^^^
  File "C:\Users\ASUS\anaconda3\Lib\site-packages\django\db\backends\mysql\base.py", line 234, in get_new_connection
    connection = Database.connect(**conn_params)
                 ^^^^^^^^^^^^^^^^^^^^^^^^^^^^^^^
  File "C:\Users\ASUS\anaconda3\Lib\site-packages\MySQLdb\__init__.py", line 121, in Connect
    return Connection(*args, **kwargs)
           ^^^^^^^^^^^^^^^^^^^^^^^^^^^
  File "C:\Users\ASUS\anaconda3\Lib\site-packages\MySQLdb\connections.py", line 200, in __init__
    super().__init__(*args, **kwargs2)
MySQLdb.OperationalError: (2002, "Can't connect to server on 'localhost' (10061)")

The above exception was the direct cause of the following exception:

Traceback (most recent call last):
  File "C:\Users\ASUS\anaconda3\Lib\site-packages\django\core\handlers\exception.py", line 47, in inner
    response = get_response(request)
               ^^^^^^^^^^^^^^^^^^^^^
  File "C:\Users\ASUS\anaconda3\Lib\site-packages\django\core\handlers\base.py", line 181, in _get_response
    response = wrapped_callback(request, *callback_args, **callback_kwargs)
               ^^^^^^^^^^^^^^^^^^^^^^^^^^^^^^^^^^^^^^^^^^^^^^^^^^^^^^^^^^^^
  File "C:\Users\ASUS\Desktop\HastaneYonetim\HastaneYonetimProjesi\hastane\views\doctor_views.py", line 51, in doctor_list
    return render(request, 'doctors.html', {'doctors': doctors, 'title': 'Doktorlar'})
           ^^^^^^^^^^^^^^^^^^^^^^^^^^^^^^^^^^^^^^^^^^^^^^^^^^^^^^^^^^^^^^^^^^^^^^^^^^^
  File "C:\Users\ASUS\anaconda3\Lib\site-packages\django\shortcuts.py", line 19, in render
    content = loader.render_to_string(template_name, context, request, using=using)
              ^^^^^^^^^^^^^^^^^^^^^^^^^^^^^^^^^^^^^^^^^^^^^^^^^^^^^^^^^^^^^^^^^^^^^
  File "C:\Users\ASUS\anaconda3\Lib\site-packages\django\template\loader.py", line 62, in render_to_string
    return template.render(context, request)
           ^^^^^^^^^^^^^^^^^^^^^^^^^^^^^^^^^
  File "C:\Users\ASUS\anaconda3\Lib\site-packages\django\template\backends\django.py", line 61, in render
    return self.template.render(context)
           ^^^^^^^^^^^^^^^^^^^^^^^^^^^^^
  File "C:\Users\ASUS\anaconda3\Lib\site-packages\django\template\base.py", line 170, in render
    return self._render(context)
           ^^^^^^^^^^^^^^^^^^^^^
  File "C:\Users\ASUS\anaconda3\Lib\site-packages\django\template\base.py", line 162, in _render
    return self.nodelist.render(context)
           ^^^^^^^^^^^^^^^^^^^^^^^^^^^^^
  File "C:\Users\ASUS\anaconda3\Lib\site-packages\django\template\base.py", line 938, in render
    bit = node.render_annotated(context)
          ^^^^^^^^^^^^^^^^^^^^^^^^^^^^^^
  File "C:\Users\ASUS\anaconda3\Lib\site-packages\django\template\base.py", line 905, in render_annotated
    return self.render(context)
           ^^^^^^^^^^^^^^^^^^^^
  File "C:\Users\ASUS\anaconda3\Lib\site-packages\django\template\loader_tags.py", line 150, in render
    return compiled_parent._render(context)
           ^^^^^^^^^^^^^^^^^^^^^^^^^^^^^^^^
  File "C:\Users\ASUS\anaconda3\Lib\site-packages\django\template\base.py", line 162, in _render
    return self.nodelist.render(context)
           ^^^^^^^^^^^^^^^^^^^^^^^^^^^^^
  File "C:\Users\ASUS\anaconda3\Lib\site-packages\django\template\base.py", line 938, in render
    bit = node.render_annotated(context)
          ^^^^^^^^^^^^^^^^^^^^^^^^^^^^^^
  File "C:\Users\ASUS\anaconda3\Lib\site-packages\django\template\base.py", line 905, in render_annotated
    return self.render(context)
           ^^^^^^^^^^^^^^^^^^^^
  File "C:\Users\ASUS\anaconda3\Lib\site-packages\django\template\loader_tags.py", line 62, in render
    result = block.nodelist.render(context)
             ^^^^^^^^^^^^^^^^^^^^^^^^^^^^^^
  File "C:\Users\ASUS\anaconda3\Lib\site-packages\django\template\base.py", line 938, in render
    bit = node.render_annotated(context)
          ^^^^^^^^^^^^^^^^^^^^^^^^^^^^^^
  File "C:\Users\ASUS\anaconda3\Lib\site-packages\django\template\base.py", line 905, in render_annotated
    return self.render(context)
           ^^^^^^^^^^^^^^^^^^^^
  File "C:\Users\ASUS\anaconda3\Lib\site-packages\django\template\defaulttags.py", line 168, in render
    len_values = len(values)
                 ^^^^^^^^^^^
  File "C:\Users\ASUS\anaconda3\Lib\site-packages\django\db\models\query.py", line 262, in __len__
    self._fetch_all()
  File "C:\Users\ASUS\anaconda3\Lib\site-packages\django\db\models\query.py", line 1324, in _fetch_all
    self._result_cache = list(self._iterable_class(self))
                         ^^^^^^^^^^^^^^^^^^^^^^^^^^^^^^^^
  File "C:\Users\ASUS\anaconda3\Lib\site-packages\django\db\models\query.py", line 51, in __iter__
    results = compiler.execute_sql(chunked_fetch=self.chunked_fetch, chunk_size=self.chunk_size)
              ^^^^^^^^^^^^^^^^^^^^^^^^^^^^^^^^^^^^^^^^^^^^^^^^^^^^^^^^^^^^^^^^^^^^^^^^^^^^^^^^^^
  File "C:\Users\ASUS\anaconda3\Lib\site-packages\django\db\models\sql\compiler.py", line 1167, in execute_sql
    cursor = self.connection.cursor()
             ^^^^^^^^^^^^^^^^^^^^^^^^
  File "C:\Users\ASUS\anaconda3\Lib\site-packages\django\utils\asyncio.py", line 26, in inner
    return func(*args, **kwargs)
           ^^^^^^^^^^^^^^^^^^^^^
  File "C:\Users\ASUS\anaconda3\Lib\site-packages\django\db\backends\base\base.py", line 259, in cursor
    return self._cursor()
           ^^^^^^^^^^^^^^
  File "C:\Users\ASUS\anaconda3\Lib\site-packages\django\db\backends\base\base.py", line 235, in _cursor
    self.ensure_connection()
  File "C:\Users\ASUS\anaconda3\Lib\site-packages\django\utils\asyncio.py", line 26, in inner
    return func(*args, **kwargs)
           ^^^^^^^^^^^^^^^^^^^^^
  File "C:\Users\ASUS\anaconda3\Lib\site-packages\django\db\backends\base\base.py", line 218, in ensure_connection
    with self.wrap_database_errors:
  File "C:\Users\ASUS\anaconda3\Lib\site-packages\django\db\utils.py", line 90, in __exit__
    raise dj_exc_value.with_traceback(traceback) from exc_value
  File "C:\Users\ASUS\anaconda3\Lib\site-packages\django\db\backends\base\base.py", line 219, in ensure_connection
    self.connect()
  File "C:\Users\ASUS\anaconda3\Lib\site-packages\django\utils\asyncio.py", line 26, in inner
    return func(*args, **kwargs)
           ^^^^^^^^^^^^^^^^^^^^^
  File "C:\Users\ASUS\anaconda3\Lib\site-packages\django\db\backends\base\base.py", line 200, in connect
    self.connection = self.get_new_connection(conn_params)
                      ^^^^^^^^^^^^^^^^^^^^^^^^^^^^^^^^^^^^
  File "C:\Users\ASUS\anaconda3\Lib\site-packages\django\utils\asyncio.py", line 26, in inner
    return func(*args, **kwargs)
           ^^^^^^^^^^^^^^^^^^^^^
  File "C:\Users\ASUS\anaconda3\Lib\site-packages\django\db\backends\mysql\base.py", line 234, in get_new_connection
    connection = Database.connect(**conn_params)
                 ^^^^^^^^^^^^^^^^^^^^^^^^^^^^^^^
  File "C:\Users\ASUS\anaconda3\Lib\site-packages\MySQLdb\__init__.py", line 121, in Connect
    return Connection(*args, **kwargs)
           ^^^^^^^^^^^^^^^^^^^^^^^^^^^
  File "C:\Users\ASUS\anaconda3\Lib\site-packages\MySQLdb\connections.py", line 200, in __init__
    super().__init__(*args, **kwargs2)
django.db.utils.OperationalError: (2002, "Can't connect to server on 'localhost' (10061)")
ERROR 2025-07-09 14:48:31,714 log Internal Server Error: /doktorlar/
Traceback (most recent call last):
  File "C:\Users\ASUS\anaconda3\Lib\site-packages\django\db\backends\base\base.py", line 219, in ensure_connection
    self.connect()
  File "C:\Users\ASUS\anaconda3\Lib\site-packages\django\utils\asyncio.py", line 26, in inner
    return func(*args, **kwargs)
           ^^^^^^^^^^^^^^^^^^^^^
  File "C:\Users\ASUS\anaconda3\Lib\site-packages\django\db\backends\base\base.py", line 200, in connect
    self.connection = self.get_new_connection(conn_params)
                      ^^^^^^^^^^^^^^^^^^^^^^^^^^^^^^^^^^^^
  File "C:\Users\ASUS\anaconda3\Lib\site-packages\django\utils\asyncio.py", line 26, in inner
    return func(*args, **kwargs)
           ^^^^^^^^^^^^^^^^^^^^^
  File "C:\Users\ASUS\anaconda3\Lib\site-packages\django\db\backends\mysql\base.py", line 234, in get_new_connection
    connection = Database.connect(**conn_params)
                 ^^^^^^^^^^^^^^^^^^^^^^^^^^^^^^^
  File "C:\Users\ASUS\anaconda3\Lib\site-packages\MySQLdb\__init__.py", line 121, in Connect
    return Connection(*args, **kwargs)
           ^^^^^^^^^^^^^^^^^^^^^^^^^^^
  File "C:\Users\ASUS\anaconda3\Lib\site-packages\MySQLdb\connections.py", line 200, in __init__
    super().__init__(*args, **kwargs2)
MySQLdb.OperationalError: (2013, "Lost connection to server at 'handshake: reading initial communication packet', system error: 0")

The above exception was the direct cause of the following exception:

Traceback (most recent call last):
  File "C:\Users\ASUS\anaconda3\Lib\site-packages\django\core\handlers\exception.py", line 47, in inner
    response = get_response(request)
               ^^^^^^^^^^^^^^^^^^^^^
  File "C:\Users\ASUS\anaconda3\Lib\site-packages\django\core\handlers\base.py", line 181, in _get_response
    response = wrapped_callback(request, *callback_args, **callback_kwargs)
               ^^^^^^^^^^^^^^^^^^^^^^^^^^^^^^^^^^^^^^^^^^^^^^^^^^^^^^^^^^^^
  File "C:\Users\ASUS\Desktop\HastaneYonetim\HastaneYonetimProjesi\hastane\views\doctor_views.py", line 51, in doctor_list
    return render(request, 'doctors.html', {'doctors': doctors, 'title': 'Doktorlar'})
           ^^^^^^^^^^^^^^^^^^^^^^^^^^^^^^^^^^^^^^^^^^^^^^^^^^^^^^^^^^^^^^^^^^^^^^^^^^^
  File "C:\Users\ASUS\anaconda3\Lib\site-packages\django\shortcuts.py", line 19, in render
    content = loader.render_to_string(template_name, context, request, using=using)
              ^^^^^^^^^^^^^^^^^^^^^^^^^^^^^^^^^^^^^^^^^^^^^^^^^^^^^^^^^^^^^^^^^^^^^
  File "C:\Users\ASUS\anaconda3\Lib\site-packages\django\template\loader.py", line 62, in render_to_string
    return template.render(context, request)
           ^^^^^^^^^^^^^^^^^^^^^^^^^^^^^^^^^
  File "C:\Users\ASUS\anaconda3\Lib\site-packages\django\template\backends\django.py", line 61, in render
    return self.template.render(context)
           ^^^^^^^^^^^^^^^^^^^^^^^^^^^^^
  File "C:\Users\ASUS\anaconda3\Lib\site-packages\django\template\base.py", line 170, in render
    return self._render(context)
           ^^^^^^^^^^^^^^^^^^^^^
  File "C:\Users\ASUS\anaconda3\Lib\site-packages\django\template\base.py", line 162, in _render
    return self.nodelist.render(context)
           ^^^^^^^^^^^^^^^^^^^^^^^^^^^^^
  File "C:\Users\ASUS\anaconda3\Lib\site-packages\django\template\base.py", line 938, in render
    bit = node.render_annotated(context)
          ^^^^^^^^^^^^^^^^^^^^^^^^^^^^^^
  File "C:\Users\ASUS\anaconda3\Lib\site-packages\django\template\base.py", line 905, in render_annotated
    return self.render(context)
           ^^^^^^^^^^^^^^^^^^^^
  File "C:\Users\ASUS\anaconda3\Lib\site-packages\django\template\loader_tags.py", line 150, in render
    return compiled_parent._render(context)
           ^^^^^^^^^^^^^^^^^^^^^^^^^^^^^^^^
  File "C:\Users\ASUS\anaconda3\Lib\site-packages\django\template\base.py", line 162, in _render
    return self.nodelist.render(context)
           ^^^^^^^^^^^^^^^^^^^^^^^^^^^^^
  File "C:\Users\ASUS\anaconda3\Lib\site-packages\django\template\base.py", line 938, in render
    bit = node.render_annotated(context)
          ^^^^^^^^^^^^^^^^^^^^^^^^^^^^^^
  File "C:\Users\ASUS\anaconda3\Lib\site-packages\django\template\base.py", line 905, in render_annotated
    return self.render(context)
           ^^^^^^^^^^^^^^^^^^^^
  File "C:\Users\ASUS\anaconda3\Lib\site-packages\django\template\loader_tags.py", line 62, in render
    result = block.nodelist.render(context)
             ^^^^^^^^^^^^^^^^^^^^^^^^^^^^^^
  File "C:\Users\ASUS\anaconda3\Lib\site-packages\django\template\base.py", line 938, in render
    bit = node.render_annotated(context)
          ^^^^^^^^^^^^^^^^^^^^^^^^^^^^^^
  File "C:\Users\ASUS\anaconda3\Lib\site-packages\django\template\base.py", line 905, in render_annotated
    return self.render(context)
           ^^^^^^^^^^^^^^^^^^^^
  File "C:\Users\ASUS\anaconda3\Lib\site-packages\django\template\defaulttags.py", line 168, in render
    len_values = len(values)
                 ^^^^^^^^^^^
  File "C:\Users\ASUS\anaconda3\Lib\site-packages\django\db\models\query.py", line 262, in __len__
    self._fetch_all()
  File "C:\Users\ASUS\anaconda3\Lib\site-packages\django\db\models\query.py", line 1324, in _fetch_all
    self._result_cache = list(self._iterable_class(self))
                         ^^^^^^^^^^^^^^^^^^^^^^^^^^^^^^^^
  File "C:\Users\ASUS\anaconda3\Lib\site-packages\django\db\models\query.py", line 51, in __iter__
    results = compiler.execute_sql(chunked_fetch=self.chunked_fetch, chunk_size=self.chunk_size)
              ^^^^^^^^^^^^^^^^^^^^^^^^^^^^^^^^^^^^^^^^^^^^^^^^^^^^^^^^^^^^^^^^^^^^^^^^^^^^^^^^^^
  File "C:\Users\ASUS\anaconda3\Lib\site-packages\django\db\models\sql\compiler.py", line 1167, in execute_sql
    cursor = self.connection.cursor()
             ^^^^^^^^^^^^^^^^^^^^^^^^
  File "C:\Users\ASUS\anaconda3\Lib\site-packages\django\utils\asyncio.py", line 26, in inner
    return func(*args, **kwargs)
           ^^^^^^^^^^^^^^^^^^^^^
  File "C:\Users\ASUS\anaconda3\Lib\site-packages\django\db\backends\base\base.py", line 259, in cursor
    return self._cursor()
           ^^^^^^^^^^^^^^
  File "C:\Users\ASUS\anaconda3\Lib\site-packages\django\db\backends\base\base.py", line 235, in _cursor
    self.ensure_connection()
  File "C:\Users\ASUS\anaconda3\Lib\site-packages\django\utils\asyncio.py", line 26, in inner
    return func(*args, **kwargs)
           ^^^^^^^^^^^^^^^^^^^^^
  File "C:\Users\ASUS\anaconda3\Lib\site-packages\django\db\backends\base\base.py", line 218, in ensure_connection
    with self.wrap_database_errors:
  File "C:\Users\ASUS\anaconda3\Lib\site-packages\django\db\utils.py", line 90, in __exit__
    raise dj_exc_value.with_traceback(traceback) from exc_value
  File "C:\Users\ASUS\anaconda3\Lib\site-packages\django\db\backends\base\base.py", line 219, in ensure_connection
    self.connect()
  File "C:\Users\ASUS\anaconda3\Lib\site-packages\django\utils\asyncio.py", line 26, in inner
    return func(*args, **kwargs)
           ^^^^^^^^^^^^^^^^^^^^^
  File "C:\Users\ASUS\anaconda3\Lib\site-packages\django\db\backends\base\base.py", line 200, in connect
    self.connection = self.get_new_connection(conn_params)
                      ^^^^^^^^^^^^^^^^^^^^^^^^^^^^^^^^^^^^
  File "C:\Users\ASUS\anaconda3\Lib\site-packages\django\utils\asyncio.py", line 26, in inner
    return func(*args, **kwargs)
           ^^^^^^^^^^^^^^^^^^^^^
  File "C:\Users\ASUS\anaconda3\Lib\site-packages\django\db\backends\mysql\base.py", line 234, in get_new_connection
    connection = Database.connect(**conn_params)
                 ^^^^^^^^^^^^^^^^^^^^^^^^^^^^^^^
  File "C:\Users\ASUS\anaconda3\Lib\site-packages\MySQLdb\__init__.py", line 121, in Connect
    return Connection(*args, **kwargs)
           ^^^^^^^^^^^^^^^^^^^^^^^^^^^
  File "C:\Users\ASUS\anaconda3\Lib\site-packages\MySQLdb\connections.py", line 200, in __init__
    super().__init__(*args, **kwargs2)
django.db.utils.OperationalError: (2013, "Lost connection to server at 'handshake: reading initial communication packet', system error: 0")
ERROR 2025-07-09 14:48:31,740 log Internal Server Error: /doktorlar/
Traceback (most recent call last):
  File "C:\Users\ASUS\anaconda3\Lib\site-packages\django\db\backends\base\base.py", line 219, in ensure_connection
    self.connect()
  File "C:\Users\ASUS\anaconda3\Lib\site-packages\django\utils\asyncio.py", line 26, in inner
    return func(*args, **kwargs)
           ^^^^^^^^^^^^^^^^^^^^^
  File "C:\Users\ASUS\anaconda3\Lib\site-packages\django\db\backends\base\base.py", line 200, in connect
    self.connection = self.get_new_connection(conn_params)
                      ^^^^^^^^^^^^^^^^^^^^^^^^^^^^^^^^^^^^
  File "C:\Users\ASUS\anaconda3\Lib\site-packages\django\utils\asyncio.py", line 26, in inner
    return func(*args, **kwargs)
           ^^^^^^^^^^^^^^^^^^^^^
  File "C:\Users\ASUS\anaconda3\Lib\site-packages\django\db\backends\mysql\base.py", line 234, in get_new_connection
    connection = Database.connect(**conn_params)
                 ^^^^^^^^^^^^^^^^^^^^^^^^^^^^^^^
  File "C:\Users\ASUS\anaconda3\Lib\site-packages\MySQLdb\__init__.py", line 121, in Connect
    return Connection(*args, **kwargs)
           ^^^^^^^^^^^^^^^^^^^^^^^^^^^
  File "C:\Users\ASUS\anaconda3\Lib\site-packages\MySQLdb\connections.py", line 200, in __init__
    super().__init__(*args, **kwargs2)
MySQLdb.OperationalError: (2002, "Can't connect to server on 'localhost' (10061)")

The above exception was the direct cause of the following exception:

Traceback (most recent call last):
  File "C:\Users\ASUS\anaconda3\Lib\site-packages\django\core\handlers\exception.py", line 47, in inner
    response = get_response(request)
               ^^^^^^^^^^^^^^^^^^^^^
  File "C:\Users\ASUS\anaconda3\Lib\site-packages\django\core\handlers\base.py", line 181, in _get_response
    response = wrapped_callback(request, *callback_args, **callback_kwargs)
               ^^^^^^^^^^^^^^^^^^^^^^^^^^^^^^^^^^^^^^^^^^^^^^^^^^^^^^^^^^^^
  File "C:\Users\ASUS\Desktop\HastaneYonetim\HastaneYonetimProjesi\hastane\views\doctor_views.py", line 51, in doctor_list
    return render(request, 'doctors.html', {'doctors': doctors, 'title': 'Doktorlar'})
           ^^^^^^^^^^^^^^^^^^^^^^^^^^^^^^^^^^^^^^^^^^^^^^^^^^^^^^^^^^^^^^^^^^^^^^^^^^^
  File "C:\Users\ASUS\anaconda3\Lib\site-packages\django\shortcuts.py", line 19, in render
    content = loader.render_to_string(template_name, context, request, using=using)
              ^^^^^^^^^^^^^^^^^^^^^^^^^^^^^^^^^^^^^^^^^^^^^^^^^^^^^^^^^^^^^^^^^^^^^
  File "C:\Users\ASUS\anaconda3\Lib\site-packages\django\template\loader.py", line 62, in render_to_string
    return template.render(context, request)
           ^^^^^^^^^^^^^^^^^^^^^^^^^^^^^^^^^
  File "C:\Users\ASUS\anaconda3\Lib\site-packages\django\template\backends\django.py", line 61, in render
    return self.template.render(context)
           ^^^^^^^^^^^^^^^^^^^^^^^^^^^^^
  File "C:\Users\ASUS\anaconda3\Lib\site-packages\django\template\base.py", line 170, in render
    return self._render(context)
           ^^^^^^^^^^^^^^^^^^^^^
  File "C:\Users\ASUS\anaconda3\Lib\site-packages\django\template\base.py", line 162, in _render
    return self.nodelist.render(context)
           ^^^^^^^^^^^^^^^^^^^^^^^^^^^^^
  File "C:\Users\ASUS\anaconda3\Lib\site-packages\django\template\base.py", line 938, in render
    bit = node.render_annotated(context)
          ^^^^^^^^^^^^^^^^^^^^^^^^^^^^^^
  File "C:\Users\ASUS\anaconda3\Lib\site-packages\django\template\base.py", line 905, in render_annotated
    return self.render(context)
           ^^^^^^^^^^^^^^^^^^^^
  File "C:\Users\ASUS\anaconda3\Lib\site-packages\django\template\loader_tags.py", line 150, in render
    return compiled_parent._render(context)
           ^^^^^^^^^^^^^^^^^^^^^^^^^^^^^^^^
  File "C:\Users\ASUS\anaconda3\Lib\site-packages\django\template\base.py", line 162, in _render
    return self.nodelist.render(context)
           ^^^^^^^^^^^^^^^^^^^^^^^^^^^^^
  File "C:\Users\ASUS\anaconda3\Lib\site-packages\django\template\base.py", line 938, in render
    bit = node.render_annotated(context)
          ^^^^^^^^^^^^^^^^^^^^^^^^^^^^^^
  File "C:\Users\ASUS\anaconda3\Lib\site-packages\django\template\base.py", line 905, in render_annotated
    return self.render(context)
           ^^^^^^^^^^^^^^^^^^^^
  File "C:\Users\ASUS\anaconda3\Lib\site-packages\django\template\loader_tags.py", line 62, in render
    result = block.nodelist.render(context)
             ^^^^^^^^^^^^^^^^^^^^^^^^^^^^^^
  File "C:\Users\ASUS\anaconda3\Lib\site-packages\django\template\base.py", line 938, in render
    bit = node.render_annotated(context)
          ^^^^^^^^^^^^^^^^^^^^^^^^^^^^^^
  File "C:\Users\ASUS\anaconda3\Lib\site-packages\django\template\base.py", line 905, in render_annotated
    return self.render(context)
           ^^^^^^^^^^^^^^^^^^^^
  File "C:\Users\ASUS\anaconda3\Lib\site-packages\django\template\defaulttags.py", line 168, in render
    len_values = len(values)
                 ^^^^^^^^^^^
  File "C:\Users\ASUS\anaconda3\Lib\site-packages\django\db\models\query.py", line 262, in __len__
    self._fetch_all()
  File "C:\Users\ASUS\anaconda3\Lib\site-packages\django\db\models\query.py", line 1324, in _fetch_all
    self._result_cache = list(self._iterable_class(self))
                         ^^^^^^^^^^^^^^^^^^^^^^^^^^^^^^^^
  File "C:\Users\ASUS\anaconda3\Lib\site-packages\django\db\models\query.py", line 51, in __iter__
    results = compiler.execute_sql(chunked_fetch=self.chunked_fetch, chunk_size=self.chunk_size)
              ^^^^^^^^^^^^^^^^^^^^^^^^^^^^^^^^^^^^^^^^^^^^^^^^^^^^^^^^^^^^^^^^^^^^^^^^^^^^^^^^^^
  File "C:\Users\ASUS\anaconda3\Lib\site-packages\django\db\models\sql\compiler.py", line 1167, in execute_sql
    cursor = self.connection.cursor()
             ^^^^^^^^^^^^^^^^^^^^^^^^
  File "C:\Users\ASUS\anaconda3\Lib\site-packages\django\utils\asyncio.py", line 26, in inner
    return func(*args, **kwargs)
           ^^^^^^^^^^^^^^^^^^^^^
  File "C:\Users\ASUS\anaconda3\Lib\site-packages\django\db\backends\base\base.py", line 259, in cursor
    return self._cursor()
           ^^^^^^^^^^^^^^
  File "C:\Users\ASUS\anaconda3\Lib\site-packages\django\db\backends\base\base.py", line 235, in _cursor
    self.ensure_connection()
  File "C:\Users\ASUS\anaconda3\Lib\site-packages\django\utils\asyncio.py", line 26, in inner
    return func(*args, **kwargs)
           ^^^^^^^^^^^^^^^^^^^^^
  File "C:\Users\ASUS\anaconda3\Lib\site-packages\django\db\backends\base\base.py", line 218, in ensure_connection
    with self.wrap_database_errors:
  File "C:\Users\ASUS\anaconda3\Lib\site-packages\django\db\utils.py", line 90, in __exit__
    raise dj_exc_value.with_traceback(traceback) from exc_value
  File "C:\Users\ASUS\anaconda3\Lib\site-packages\django\db\backends\base\base.py", line 219, in ensure_connection
    self.connect()
  File "C:\Users\ASUS\anaconda3\Lib\site-packages\django\utils\asyncio.py", line 26, in inner
    return func(*args, **kwargs)
           ^^^^^^^^^^^^^^^^^^^^^
  File "C:\Users\ASUS\anaconda3\Lib\site-packages\django\db\backends\base\base.py", line 200, in connect
    self.connection = self.get_new_connection(conn_params)
                      ^^^^^^^^^^^^^^^^^^^^^^^^^^^^^^^^^^^^
  File "C:\Users\ASUS\anaconda3\Lib\site-packages\django\utils\asyncio.py", line 26, in inner
    return func(*args, **kwargs)
           ^^^^^^^^^^^^^^^^^^^^^
  File "C:\Users\ASUS\anaconda3\Lib\site-packages\django\db\backends\mysql\base.py", line 234, in get_new_connection
    connection = Database.connect(**conn_params)
                 ^^^^^^^^^^^^^^^^^^^^^^^^^^^^^^^
  File "C:\Users\ASUS\anaconda3\Lib\site-packages\MySQLdb\__init__.py", line 121, in Connect
    return Connection(*args, **kwargs)
           ^^^^^^^^^^^^^^^^^^^^^^^^^^^
  File "C:\Users\ASUS\anaconda3\Lib\site-packages\MySQLdb\connections.py", line 200, in __init__
    super().__init__(*args, **kwargs2)
django.db.utils.OperationalError: (2002, "Can't connect to server on 'localhost' (10061)")
ERROR 2025-07-09 14:48:31,782 log Internal Server Error: /doktorlar/
Traceback (most recent call last):
  File "C:\Users\ASUS\anaconda3\Lib\site-packages\django\db\backends\base\base.py", line 219, in ensure_connection
    self.connect()
  File "C:\Users\ASUS\anaconda3\Lib\site-packages\django\utils\asyncio.py", line 26, in inner
    return func(*args, **kwargs)
           ^^^^^^^^^^^^^^^^^^^^^
  File "C:\Users\ASUS\anaconda3\Lib\site-packages\django\db\backends\base\base.py", line 200, in connect
    self.connection = self.get_new_connection(conn_params)
                      ^^^^^^^^^^^^^^^^^^^^^^^^^^^^^^^^^^^^
  File "C:\Users\ASUS\anaconda3\Lib\site-packages\django\utils\asyncio.py", line 26, in inner
    return func(*args, **kwargs)
           ^^^^^^^^^^^^^^^^^^^^^
  File "C:\Users\ASUS\anaconda3\Lib\site-packages\django\db\backends\mysql\base.py", line 234, in get_new_connection
    connection = Database.connect(**conn_params)
                 ^^^^^^^^^^^^^^^^^^^^^^^^^^^^^^^
  File "C:\Users\ASUS\anaconda3\Lib\site-packages\MySQLdb\__init__.py", line 121, in Connect
    return Connection(*args, **kwargs)
           ^^^^^^^^^^^^^^^^^^^^^^^^^^^
  File "C:\Users\ASUS\anaconda3\Lib\site-packages\MySQLdb\connections.py", line 200, in __init__
    super().__init__(*args, **kwargs2)
MySQLdb.OperationalError: (2002, "Can't connect to server on 'localhost' (10061)")

The above exception was the direct cause of the following exception:

Traceback (most recent call last):
  File "C:\Users\ASUS\anaconda3\Lib\site-packages\django\core\handlers\exception.py", line 47, in inner
    response = get_response(request)
               ^^^^^^^^^^^^^^^^^^^^^
  File "C:\Users\ASUS\anaconda3\Lib\site-packages\django\core\handlers\base.py", line 181, in _get_response
    response = wrapped_callback(request, *callback_args, **callback_kwargs)
               ^^^^^^^^^^^^^^^^^^^^^^^^^^^^^^^^^^^^^^^^^^^^^^^^^^^^^^^^^^^^
  File "C:\Users\ASUS\Desktop\HastaneYonetim\HastaneYonetimProjesi\hastane\views\doctor_views.py", line 51, in doctor_list
    return render(request, 'doctors.html', {'doctors': doctors, 'title': 'Doktorlar'})
           ^^^^^^^^^^^^^^^^^^^^^^^^^^^^^^^^^^^^^^^^^^^^^^^^^^^^^^^^^^^^^^^^^^^^^^^^^^^
  File "C:\Users\ASUS\anaconda3\Lib\site-packages\django\shortcuts.py", line 19, in render
    content = loader.render_to_string(template_name, context, request, using=using)
              ^^^^^^^^^^^^^^^^^^^^^^^^^^^^^^^^^^^^^^^^^^^^^^^^^^^^^^^^^^^^^^^^^^^^^
  File "C:\Users\ASUS\anaconda3\Lib\site-packages\django\template\loader.py", line 62, in render_to_string
    return template.render(context, request)
           ^^^^^^^^^^^^^^^^^^^^^^^^^^^^^^^^^
  File "C:\Users\ASUS\anaconda3\Lib\site-packages\django\template\backends\django.py", line 61, in render
    return self.template.render(context)
           ^^^^^^^^^^^^^^^^^^^^^^^^^^^^^
  File "C:\Users\ASUS\anaconda3\Lib\site-packages\django\template\base.py", line 170, in render
    return self._render(context)
           ^^^^^^^^^^^^^^^^^^^^^
  File "C:\Users\ASUS\anaconda3\Lib\site-packages\django\template\base.py", line 162, in _render
    return self.nodelist.render(context)
           ^^^^^^^^^^^^^^^^^^^^^^^^^^^^^
  File "C:\Users\ASUS\anaconda3\Lib\site-packages\django\template\base.py", line 938, in render
    bit = node.render_annotated(context)
          ^^^^^^^^^^^^^^^^^^^^^^^^^^^^^^
  File "C:\Users\ASUS\anaconda3\Lib\site-packages\django\template\base.py", line 905, in render_annotated
    return self.render(context)
           ^^^^^^^^^^^^^^^^^^^^
  File "C:\Users\ASUS\anaconda3\Lib\site-packages\django\template\loader_tags.py", line 150, in render
    return compiled_parent._render(context)
           ^^^^^^^^^^^^^^^^^^^^^^^^^^^^^^^^
  File "C:\Users\ASUS\anaconda3\Lib\site-packages\django\template\base.py", line 162, in _render
    return self.nodelist.render(context)
           ^^^^^^^^^^^^^^^^^^^^^^^^^^^^^
  File "C:\Users\ASUS\anaconda3\Lib\site-packages\django\template\base.py", line 938, in render
    bit = node.render_annotated(context)
          ^^^^^^^^^^^^^^^^^^^^^^^^^^^^^^
  File "C:\Users\ASUS\anaconda3\Lib\site-packages\django\template\base.py", line 905, in render_annotated
    return self.render(context)
           ^^^^^^^^^^^^^^^^^^^^
  File "C:\Users\ASUS\anaconda3\Lib\site-packages\django\template\loader_tags.py", line 62, in render
    result = block.nodelist.render(context)
             ^^^^^^^^^^^^^^^^^^^^^^^^^^^^^^
  File "C:\Users\ASUS\anaconda3\Lib\site-packages\django\template\base.py", line 938, in render
    bit = node.render_annotated(context)
          ^^^^^^^^^^^^^^^^^^^^^^^^^^^^^^
  File "C:\Users\ASUS\anaconda3\Lib\site-packages\django\template\base.py", line 905, in render_annotated
    return self.render(context)
           ^^^^^^^^^^^^^^^^^^^^
  File "C:\Users\ASUS\anaconda3\Lib\site-packages\django\template\defaulttags.py", line 168, in render
    len_values = len(values)
                 ^^^^^^^^^^^
  File "C:\Users\ASUS\anaconda3\Lib\site-packages\django\db\models\query.py", line 262, in __len__
    self._fetch_all()
  File "C:\Users\ASUS\anaconda3\Lib\site-packages\django\db\models\query.py", line 1324, in _fetch_all
    self._result_cache = list(self._iterable_class(self))
                         ^^^^^^^^^^^^^^^^^^^^^^^^^^^^^^^^
  File "C:\Users\ASUS\anaconda3\Lib\site-packages\django\db\models\query.py", line 51, in __iter__
    results = compiler.execute_sql(chunked_fetch=self.chunked_fetch, chunk_size=self.chunk_size)
              ^^^^^^^^^^^^^^^^^^^^^^^^^^^^^^^^^^^^^^^^^^^^^^^^^^^^^^^^^^^^^^^^^^^^^^^^^^^^^^^^^^
  File "C:\Users\ASUS\anaconda3\Lib\site-packages\django\db\models\sql\compiler.py", line 1167, in execute_sql
    cursor = self.connection.cursor()
             ^^^^^^^^^^^^^^^^^^^^^^^^
  File "C:\Users\ASUS\anaconda3\Lib\site-packages\django\utils\asyncio.py", line 26, in inner
    return func(*args, **kwargs)
           ^^^^^^^^^^^^^^^^^^^^^
  File "C:\Users\ASUS\anaconda3\Lib\site-packages\django\db\backends\base\base.py", line 259, in cursor
    return self._cursor()
           ^^^^^^^^^^^^^^
  File "C:\Users\ASUS\anaconda3\Lib\site-packages\django\db\backends\base\base.py", line 235, in _cursor
    self.ensure_connection()
  File "C:\Users\ASUS\anaconda3\Lib\site-packages\django\utils\asyncio.py", line 26, in inner
    return func(*args, **kwargs)
           ^^^^^^^^^^^^^^^^^^^^^
  File "C:\Users\ASUS\anaconda3\Lib\site-packages\django\db\backends\base\base.py", line 218, in ensure_connection
    with self.wrap_database_errors:
  File "C:\Users\ASUS\anaconda3\Lib\site-packages\django\db\utils.py", line 90, in __exit__
    raise dj_exc_value.with_traceback(traceback) from exc_value
  File "C:\Users\ASUS\anaconda3\Lib\site-packages\django\db\backends\base\base.py", line 219, in ensure_connection
    self.connect()
  File "C:\Users\ASUS\anaconda3\Lib\site-packages\django\utils\asyncio.py", line 26, in inner
    return func(*args, **kwargs)
           ^^^^^^^^^^^^^^^^^^^^^
  File "C:\Users\ASUS\anaconda3\Lib\site-packages\django\db\backends\base\base.py", line 200, in connect
    self.connection = self.get_new_connection(conn_params)
                      ^^^^^^^^^^^^^^^^^^^^^^^^^^^^^^^^^^^^
  File "C:\Users\ASUS\anaconda3\Lib\site-packages\django\utils\asyncio.py", line 26, in inner
    return func(*args, **kwargs)
           ^^^^^^^^^^^^^^^^^^^^^
  File "C:\Users\ASUS\anaconda3\Lib\site-packages\django\db\backends\mysql\base.py", line 234, in get_new_connection
    connection = Database.connect(**conn_params)
                 ^^^^^^^^^^^^^^^^^^^^^^^^^^^^^^^
  File "C:\Users\ASUS\anaconda3\Lib\site-packages\MySQLdb\__init__.py", line 121, in Connect
    return Connection(*args, **kwargs)
           ^^^^^^^^^^^^^^^^^^^^^^^^^^^
  File "C:\Users\ASUS\anaconda3\Lib\site-packages\MySQLdb\connections.py", line 200, in __init__
    super().__init__(*args, **kwargs2)
django.db.utils.OperationalError: (2002, "Can't connect to server on 'localhost' (10061)")
ERROR 2025-07-09 15:54:31,019 log Internal Server Error: /
Traceback (most recent call last):
  File "C:\Users\ASUS\anaconda3\Lib\site-packages\django\template\backends\django.py", line 61, in render
    return self.template.render(context)
           ^^^^^^^^^^^^^^^^^^^^^^^^^^^^^
  File "C:\Users\ASUS\anaconda3\Lib\site-packages\django\template\base.py", line 170, in render
    return self._render(context)
           ^^^^^^^^^^^^^^^^^^^^^
  File "C:\Users\ASUS\anaconda3\Lib\site-packages\django\template\base.py", line 162, in _render
    return self.nodelist.render(context)
           ^^^^^^^^^^^^^^^^^^^^^^^^^^^^^
  File "C:\Users\ASUS\anaconda3\Lib\site-packages\django\template\base.py", line 938, in render
    bit = node.render_annotated(context)
          ^^^^^^^^^^^^^^^^^^^^^^^^^^^^^^
  File "C:\Users\ASUS\anaconda3\Lib\site-packages\django\template\base.py", line 905, in render_annotated
    return self.render(context)
           ^^^^^^^^^^^^^^^^^^^^
  File "C:\Users\ASUS\anaconda3\Lib\site-packages\django\template\loader_tags.py", line 127, in render
    compiled_parent = self.get_parent(context)
                      ^^^^^^^^^^^^^^^^^^^^^^^^
  File "C:\Users\ASUS\anaconda3\Lib\site-packages\django\template\loader_tags.py", line 124, in get_parent
    return self.find_template(parent, context)
           ^^^^^^^^^^^^^^^^^^^^^^^^^^^^^^^^^^^
  File "C:\Users\ASUS\anaconda3\Lib\site-packages\django\template\loader_tags.py", line 103, in find_template
    template, origin = context.template.engine.find_template(
                       ^^^^^^^^^^^^^^^^^^^^^^^^^^^^^^^^^^^^^^
  File "C:\Users\ASUS\anaconda3\Lib\site-packages\django\template\engine.py", line 129, in find_template
    raise TemplateDoesNotExist(name, tried=tried)
django.template.exceptions.TemplateDoesNotExist: base_login.html

The above exception was the direct cause of the following exception:

Traceback (most recent call last):
  File "C:\Users\ASUS\anaconda3\Lib\site-packages\django\core\handlers\exception.py", line 47, in inner
    response = get_response(request)
               ^^^^^^^^^^^^^^^^^^^^^
  File "C:\Users\ASUS\anaconda3\Lib\site-packages\django\core\handlers\base.py", line 181, in _get_response
    response = wrapped_callback(request, *callback_args, **callback_kwargs)
               ^^^^^^^^^^^^^^^^^^^^^^^^^^^^^^^^^^^^^^^^^^^^^^^^^^^^^^^^^^^^
  File "C:\Users\ASUS\Desktop\HastaneYonetim\HastaneYonetimProjesi\hastane\views\login_views.py", line 6, in login_select_view
    return render(request, 'loginpage/login_select.html')
           ^^^^^^^^^^^^^^^^^^^^^^^^^^^^^^^^^^^^^^^^^^^^^^
  File "C:\Users\ASUS\anaconda3\Lib\site-packages\django\shortcuts.py", line 19, in render
    content = loader.render_to_string(template_name, context, request, using=using)
              ^^^^^^^^^^^^^^^^^^^^^^^^^^^^^^^^^^^^^^^^^^^^^^^^^^^^^^^^^^^^^^^^^^^^^
  File "C:\Users\ASUS\anaconda3\Lib\site-packages\django\template\loader.py", line 62, in render_to_string
    return template.render(context, request)
           ^^^^^^^^^^^^^^^^^^^^^^^^^^^^^^^^^
  File "C:\Users\ASUS\anaconda3\Lib\site-packages\django\template\backends\django.py", line 63, in render
    reraise(exc, self.backend)
  File "C:\Users\ASUS\anaconda3\Lib\site-packages\django\template\backends\django.py", line 84, in reraise
    raise new from exc
django.template.exceptions.TemplateDoesNotExist: base_login.html
ERROR 2025-07-09 15:54:31,029 basehttp "GET / HTTP/1.1" 500 126016
ERROR 2025-07-09 15:58:14,874 log Internal Server Error: /login/
Traceback (most recent call last):
  File "C:\Users\ASUS\anaconda3\Lib\site-packages\django\template\backends\django.py", line 61, in render
    return self.template.render(context)
           ^^^^^^^^^^^^^^^^^^^^^^^^^^^^^
  File "C:\Users\ASUS\anaconda3\Lib\site-packages\django\template\base.py", line 170, in render
    return self._render(context)
           ^^^^^^^^^^^^^^^^^^^^^
  File "C:\Users\ASUS\anaconda3\Lib\site-packages\django\template\base.py", line 162, in _render
    return self.nodelist.render(context)
           ^^^^^^^^^^^^^^^^^^^^^^^^^^^^^
  File "C:\Users\ASUS\anaconda3\Lib\site-packages\django\template\base.py", line 938, in render
    bit = node.render_annotated(context)
          ^^^^^^^^^^^^^^^^^^^^^^^^^^^^^^
  File "C:\Users\ASUS\anaconda3\Lib\site-packages\django\template\base.py", line 905, in render_annotated
    return self.render(context)
           ^^^^^^^^^^^^^^^^^^^^
  File "C:\Users\ASUS\anaconda3\Lib\site-packages\django\template\loader_tags.py", line 127, in render
    compiled_parent = self.get_parent(context)
                      ^^^^^^^^^^^^^^^^^^^^^^^^
  File "C:\Users\ASUS\anaconda3\Lib\site-packages\django\template\loader_tags.py", line 124, in get_parent
    return self.find_template(parent, context)
           ^^^^^^^^^^^^^^^^^^^^^^^^^^^^^^^^^^^
  File "C:\Users\ASUS\anaconda3\Lib\site-packages\django\template\loader_tags.py", line 103, in find_template
    template, origin = context.template.engine.find_template(
                       ^^^^^^^^^^^^^^^^^^^^^^^^^^^^^^^^^^^^^^
  File "C:\Users\ASUS\anaconda3\Lib\site-packages\django\template\engine.py", line 129, in find_template
    raise TemplateDoesNotExist(name, tried=tried)
django.template.exceptions.TemplateDoesNotExist: base_login.html

The above exception was the direct cause of the following exception:

Traceback (most recent call last):
  File "C:\Users\ASUS\anaconda3\Lib\site-packages\django\core\handlers\exception.py", line 47, in inner
    response = get_response(request)
               ^^^^^^^^^^^^^^^^^^^^^
  File "C:\Users\ASUS\anaconda3\Lib\site-packages\django\core\handlers\base.py", line 181, in _get_response
    response = wrapped_callback(request, *callback_args, **callback_kwargs)
               ^^^^^^^^^^^^^^^^^^^^^^^^^^^^^^^^^^^^^^^^^^^^^^^^^^^^^^^^^^^^
  File "C:\Users\ASUS\Desktop\HastaneYonetim\HastaneYonetimProjesi\hastane\views\login_views.py", line 6, in login_select_view
    return render(request, 'loginpage/login_select.html')
           ^^^^^^^^^^^^^^^^^^^^^^^^^^^^^^^^^^^^^^^^^^^^^^
  File "C:\Users\ASUS\anaconda3\Lib\site-packages\django\shortcuts.py", line 19, in render
    content = loader.render_to_string(template_name, context, request, using=using)
              ^^^^^^^^^^^^^^^^^^^^^^^^^^^^^^^^^^^^^^^^^^^^^^^^^^^^^^^^^^^^^^^^^^^^^
  File "C:\Users\ASUS\anaconda3\Lib\site-packages\django\template\loader.py", line 62, in render_to_string
    return template.render(context, request)
           ^^^^^^^^^^^^^^^^^^^^^^^^^^^^^^^^^
  File "C:\Users\ASUS\anaconda3\Lib\site-packages\django\template\backends\django.py", line 63, in render
    reraise(exc, self.backend)
  File "C:\Users\ASUS\anaconda3\Lib\site-packages\django\template\backends\django.py", line 84, in reraise
    raise new from exc
django.template.exceptions.TemplateDoesNotExist: base_login.html
ERROR 2025-07-09 15:58:14,883 basehttp "GET /login/ HTTP/1.1" 500 126237
ERROR 2025-07-09 15:58:15,819 log Internal Server Error: /
Traceback (most recent call last):
  File "C:\Users\ASUS\anaconda3\Lib\site-packages\django\template\backends\django.py", line 61, in render
    return self.template.render(context)
           ^^^^^^^^^^^^^^^^^^^^^^^^^^^^^
  File "C:\Users\ASUS\anaconda3\Lib\site-packages\django\template\base.py", line 170, in render
    return self._render(context)
           ^^^^^^^^^^^^^^^^^^^^^
  File "C:\Users\ASUS\anaconda3\Lib\site-packages\django\template\base.py", line 162, in _render
    return self.nodelist.render(context)
           ^^^^^^^^^^^^^^^^^^^^^^^^^^^^^
  File "C:\Users\ASUS\anaconda3\Lib\site-packages\django\template\base.py", line 938, in render
    bit = node.render_annotated(context)
          ^^^^^^^^^^^^^^^^^^^^^^^^^^^^^^
  File "C:\Users\ASUS\anaconda3\Lib\site-packages\django\template\base.py", line 905, in render_annotated
    return self.render(context)
           ^^^^^^^^^^^^^^^^^^^^
  File "C:\Users\ASUS\anaconda3\Lib\site-packages\django\template\loader_tags.py", line 127, in render
    compiled_parent = self.get_parent(context)
                      ^^^^^^^^^^^^^^^^^^^^^^^^
  File "C:\Users\ASUS\anaconda3\Lib\site-packages\django\template\loader_tags.py", line 124, in get_parent
    return self.find_template(parent, context)
           ^^^^^^^^^^^^^^^^^^^^^^^^^^^^^^^^^^^
  File "C:\Users\ASUS\anaconda3\Lib\site-packages\django\template\loader_tags.py", line 103, in find_template
    template, origin = context.template.engine.find_template(
                       ^^^^^^^^^^^^^^^^^^^^^^^^^^^^^^^^^^^^^^
  File "C:\Users\ASUS\anaconda3\Lib\site-packages\django\template\engine.py", line 129, in find_template
    raise TemplateDoesNotExist(name, tried=tried)
django.template.exceptions.TemplateDoesNotExist: base_login.html

The above exception was the direct cause of the following exception:

Traceback (most recent call last):
  File "C:\Users\ASUS\anaconda3\Lib\site-packages\django\core\handlers\exception.py", line 47, in inner
    response = get_response(request)
               ^^^^^^^^^^^^^^^^^^^^^
  File "C:\Users\ASUS\anaconda3\Lib\site-packages\django\core\handlers\base.py", line 181, in _get_response
    response = wrapped_callback(request, *callback_args, **callback_kwargs)
               ^^^^^^^^^^^^^^^^^^^^^^^^^^^^^^^^^^^^^^^^^^^^^^^^^^^^^^^^^^^^
  File "C:\Users\ASUS\Desktop\HastaneYonetim\HastaneYonetimProjesi\hastane\views\login_views.py", line 6, in login_select_view
    return render(request, 'loginpage/login_select.html')
           ^^^^^^^^^^^^^^^^^^^^^^^^^^^^^^^^^^^^^^^^^^^^^^
  File "C:\Users\ASUS\anaconda3\Lib\site-packages\django\shortcuts.py", line 19, in render
    content = loader.render_to_string(template_name, context, request, using=using)
              ^^^^^^^^^^^^^^^^^^^^^^^^^^^^^^^^^^^^^^^^^^^^^^^^^^^^^^^^^^^^^^^^^^^^^
  File "C:\Users\ASUS\anaconda3\Lib\site-packages\django\template\loader.py", line 62, in render_to_string
    return template.render(context, request)
           ^^^^^^^^^^^^^^^^^^^^^^^^^^^^^^^^^
  File "C:\Users\ASUS\anaconda3\Lib\site-packages\django\template\backends\django.py", line 63, in render
    reraise(exc, self.backend)
  File "C:\Users\ASUS\anaconda3\Lib\site-packages\django\template\backends\django.py", line 84, in reraise
    raise new from exc
django.template.exceptions.TemplateDoesNotExist: base_login.html
ERROR 2025-07-09 15:58:15,823 basehttp "GET / HTTP/1.1" 500 126016
ERROR 2025-07-09 15:58:19,126 log Internal Server Error: /login/
Traceback (most recent call last):
  File "C:\Users\ASUS\anaconda3\Lib\site-packages\django\template\backends\django.py", line 61, in render
    return self.template.render(context)
           ^^^^^^^^^^^^^^^^^^^^^^^^^^^^^
  File "C:\Users\ASUS\anaconda3\Lib\site-packages\django\template\base.py", line 170, in render
    return self._render(context)
           ^^^^^^^^^^^^^^^^^^^^^
  File "C:\Users\ASUS\anaconda3\Lib\site-packages\django\template\base.py", line 162, in _render
    return self.nodelist.render(context)
           ^^^^^^^^^^^^^^^^^^^^^^^^^^^^^
  File "C:\Users\ASUS\anaconda3\Lib\site-packages\django\template\base.py", line 938, in render
    bit = node.render_annotated(context)
          ^^^^^^^^^^^^^^^^^^^^^^^^^^^^^^
  File "C:\Users\ASUS\anaconda3\Lib\site-packages\django\template\base.py", line 905, in render_annotated
    return self.render(context)
           ^^^^^^^^^^^^^^^^^^^^
  File "C:\Users\ASUS\anaconda3\Lib\site-packages\django\template\loader_tags.py", line 127, in render
    compiled_parent = self.get_parent(context)
                      ^^^^^^^^^^^^^^^^^^^^^^^^
  File "C:\Users\ASUS\anaconda3\Lib\site-packages\django\template\loader_tags.py", line 124, in get_parent
    return self.find_template(parent, context)
           ^^^^^^^^^^^^^^^^^^^^^^^^^^^^^^^^^^^
  File "C:\Users\ASUS\anaconda3\Lib\site-packages\django\template\loader_tags.py", line 103, in find_template
    template, origin = context.template.engine.find_template(
                       ^^^^^^^^^^^^^^^^^^^^^^^^^^^^^^^^^^^^^^
  File "C:\Users\ASUS\anaconda3\Lib\site-packages\django\template\engine.py", line 129, in find_template
    raise TemplateDoesNotExist(name, tried=tried)
django.template.exceptions.TemplateDoesNotExist: base_login.html

The above exception was the direct cause of the following exception:

Traceback (most recent call last):
  File "C:\Users\ASUS\anaconda3\Lib\site-packages\django\core\handlers\exception.py", line 47, in inner
    response = get_response(request)
               ^^^^^^^^^^^^^^^^^^^^^
  File "C:\Users\ASUS\anaconda3\Lib\site-packages\django\core\handlers\base.py", line 181, in _get_response
    response = wrapped_callback(request, *callback_args, **callback_kwargs)
               ^^^^^^^^^^^^^^^^^^^^^^^^^^^^^^^^^^^^^^^^^^^^^^^^^^^^^^^^^^^^
  File "C:\Users\ASUS\Desktop\HastaneYonetim\HastaneYonetimProjesi\hastane\views\login_views.py", line 6, in login_select_view
    return render(request, 'loginpage/login_select.html')
           ^^^^^^^^^^^^^^^^^^^^^^^^^^^^^^^^^^^^^^^^^^^^^^
  File "C:\Users\ASUS\anaconda3\Lib\site-packages\django\shortcuts.py", line 19, in render
    content = loader.render_to_string(template_name, context, request, using=using)
              ^^^^^^^^^^^^^^^^^^^^^^^^^^^^^^^^^^^^^^^^^^^^^^^^^^^^^^^^^^^^^^^^^^^^^
  File "C:\Users\ASUS\anaconda3\Lib\site-packages\django\template\loader.py", line 62, in render_to_string
    return template.render(context, request)
           ^^^^^^^^^^^^^^^^^^^^^^^^^^^^^^^^^
  File "C:\Users\ASUS\anaconda3\Lib\site-packages\django\template\backends\django.py", line 63, in render
    reraise(exc, self.backend)
  File "C:\Users\ASUS\anaconda3\Lib\site-packages\django\template\backends\django.py", line 84, in reraise
    raise new from exc
django.template.exceptions.TemplateDoesNotExist: base_login.html
ERROR 2025-07-09 15:58:19,128 basehttp "GET /login/ HTTP/1.1" 500 126100
ERROR 2025-07-09 16:04:26,100 log Internal Server Error: /login/admin/
Traceback (most recent call last):
  File "C:\Users\ASUS\anaconda3\Lib\site-packages\django\template\backends\django.py", line 61, in render
    return self.template.render(context)
           ^^^^^^^^^^^^^^^^^^^^^^^^^^^^^
  File "C:\Users\ASUS\anaconda3\Lib\site-packages\django\template\base.py", line 170, in render
    return self._render(context)
           ^^^^^^^^^^^^^^^^^^^^^
  File "C:\Users\ASUS\anaconda3\Lib\site-packages\django\template\base.py", line 162, in _render
    return self.nodelist.render(context)
           ^^^^^^^^^^^^^^^^^^^^^^^^^^^^^
  File "C:\Users\ASUS\anaconda3\Lib\site-packages\django\template\base.py", line 938, in render
    bit = node.render_annotated(context)
          ^^^^^^^^^^^^^^^^^^^^^^^^^^^^^^
  File "C:\Users\ASUS\anaconda3\Lib\site-packages\django\template\base.py", line 905, in render_annotated
    return self.render(context)
           ^^^^^^^^^^^^^^^^^^^^
  File "C:\Users\ASUS\anaconda3\Lib\site-packages\django\template\loader_tags.py", line 127, in render
    compiled_parent = self.get_parent(context)
                      ^^^^^^^^^^^^^^^^^^^^^^^^
  File "C:\Users\ASUS\anaconda3\Lib\site-packages\django\template\loader_tags.py", line 124, in get_parent
    return self.find_template(parent, context)
           ^^^^^^^^^^^^^^^^^^^^^^^^^^^^^^^^^^^
  File "C:\Users\ASUS\anaconda3\Lib\site-packages\django\template\loader_tags.py", line 103, in find_template
    template, origin = context.template.engine.find_template(
                       ^^^^^^^^^^^^^^^^^^^^^^^^^^^^^^^^^^^^^^
  File "C:\Users\ASUS\anaconda3\Lib\site-packages\django\template\engine.py", line 129, in find_template
    raise TemplateDoesNotExist(name, tried=tried)
django.template.exceptions.TemplateDoesNotExist: base_login.html

The above exception was the direct cause of the following exception:

Traceback (most recent call last):
  File "C:\Users\ASUS\anaconda3\Lib\site-packages\django\core\handlers\exception.py", line 47, in inner
    response = get_response(request)
               ^^^^^^^^^^^^^^^^^^^^^
  File "C:\Users\ASUS\anaconda3\Lib\site-packages\django\core\handlers\base.py", line 181, in _get_response
    response = wrapped_callback(request, *callback_args, **callback_kwargs)
               ^^^^^^^^^^^^^^^^^^^^^^^^^^^^^^^^^^^^^^^^^^^^^^^^^^^^^^^^^^^^
  File "C:\Users\ASUS\Desktop\HastaneYonetim\HastaneYonetimProjesi\hastane\views\login_views.py", line 9, in admin_login_view
    return render(request, 'loginpage/admin_login.html')
           ^^^^^^^^^^^^^^^^^^^^^^^^^^^^^^^^^^^^^^^^^^^^^
  File "C:\Users\ASUS\anaconda3\Lib\site-packages\django\shortcuts.py", line 19, in render
    content = loader.render_to_string(template_name, context, request, using=using)
              ^^^^^^^^^^^^^^^^^^^^^^^^^^^^^^^^^^^^^^^^^^^^^^^^^^^^^^^^^^^^^^^^^^^^^
  File "C:\Users\ASUS\anaconda3\Lib\site-packages\django\template\loader.py", line 62, in render_to_string
    return template.render(context, request)
           ^^^^^^^^^^^^^^^^^^^^^^^^^^^^^^^^^
  File "C:\Users\ASUS\anaconda3\Lib\site-packages\django\template\backends\django.py", line 63, in render
    reraise(exc, self.backend)
  File "C:\Users\ASUS\anaconda3\Lib\site-packages\django\template\backends\django.py", line 84, in reraise
    raise new from exc
django.template.exceptions.TemplateDoesNotExist: base_login.html
ERROR 2025-07-09 16:04:26,110 basehttp "GET /login/admin/ HTTP/1.1" 500 126765
ERROR 2025-07-09 16:04:30,910 log Internal Server Error: /login/admin/
Traceback (most recent call last):
  File "C:\Users\ASUS\anaconda3\Lib\site-packages\django\template\backends\django.py", line 61, in render
    return self.template.render(context)
           ^^^^^^^^^^^^^^^^^^^^^^^^^^^^^
  File "C:\Users\ASUS\anaconda3\Lib\site-packages\django\template\base.py", line 170, in render
    return self._render(context)
           ^^^^^^^^^^^^^^^^^^^^^
  File "C:\Users\ASUS\anaconda3\Lib\site-packages\django\template\base.py", line 162, in _render
    return self.nodelist.render(context)
           ^^^^^^^^^^^^^^^^^^^^^^^^^^^^^
  File "C:\Users\ASUS\anaconda3\Lib\site-packages\django\template\base.py", line 938, in render
    bit = node.render_annotated(context)
          ^^^^^^^^^^^^^^^^^^^^^^^^^^^^^^
  File "C:\Users\ASUS\anaconda3\Lib\site-packages\django\template\base.py", line 905, in render_annotated
    return self.render(context)
           ^^^^^^^^^^^^^^^^^^^^
  File "C:\Users\ASUS\anaconda3\Lib\site-packages\django\template\loader_tags.py", line 127, in render
    compiled_parent = self.get_parent(context)
                      ^^^^^^^^^^^^^^^^^^^^^^^^
  File "C:\Users\ASUS\anaconda3\Lib\site-packages\django\template\loader_tags.py", line 124, in get_parent
    return self.find_template(parent, context)
           ^^^^^^^^^^^^^^^^^^^^^^^^^^^^^^^^^^^
  File "C:\Users\ASUS\anaconda3\Lib\site-packages\django\template\loader_tags.py", line 103, in find_template
    template, origin = context.template.engine.find_template(
                       ^^^^^^^^^^^^^^^^^^^^^^^^^^^^^^^^^^^^^^
  File "C:\Users\ASUS\anaconda3\Lib\site-packages\django\template\engine.py", line 129, in find_template
    raise TemplateDoesNotExist(name, tried=tried)
django.template.exceptions.TemplateDoesNotExist: base_login.html

The above exception was the direct cause of the following exception:

Traceback (most recent call last):
  File "C:\Users\ASUS\anaconda3\Lib\site-packages\django\core\handlers\exception.py", line 47, in inner
    response = get_response(request)
               ^^^^^^^^^^^^^^^^^^^^^
  File "C:\Users\ASUS\anaconda3\Lib\site-packages\django\core\handlers\base.py", line 181, in _get_response
    response = wrapped_callback(request, *callback_args, **callback_kwargs)
               ^^^^^^^^^^^^^^^^^^^^^^^^^^^^^^^^^^^^^^^^^^^^^^^^^^^^^^^^^^^^
  File "C:\Users\ASUS\Desktop\HastaneYonetim\HastaneYonetimProjesi\hastane\views\login_views.py", line 9, in admin_login_view
    return render(request, 'loginpage/admin_login.html')
           ^^^^^^^^^^^^^^^^^^^^^^^^^^^^^^^^^^^^^^^^^^^^^
  File "C:\Users\ASUS\anaconda3\Lib\site-packages\django\shortcuts.py", line 19, in render
    content = loader.render_to_string(template_name, context, request, using=using)
              ^^^^^^^^^^^^^^^^^^^^^^^^^^^^^^^^^^^^^^^^^^^^^^^^^^^^^^^^^^^^^^^^^^^^^
  File "C:\Users\ASUS\anaconda3\Lib\site-packages\django\template\loader.py", line 62, in render_to_string
    return template.render(context, request)
           ^^^^^^^^^^^^^^^^^^^^^^^^^^^^^^^^^
  File "C:\Users\ASUS\anaconda3\Lib\site-packages\django\template\backends\django.py", line 63, in render
    reraise(exc, self.backend)
  File "C:\Users\ASUS\anaconda3\Lib\site-packages\django\template\backends\django.py", line 84, in reraise
    raise new from exc
django.template.exceptions.TemplateDoesNotExist: base_login.html
ERROR 2025-07-09 16:04:30,912 basehttp "GET /login/admin/ HTTP/1.1" 500 126628
ERROR 2025-07-31 15:41:04,970 log Internal Server Error: /randevu/doktor-uygunluk/9/
Traceback (most recent call last):
  File "C:\Users\ASUS\anaconda3\Lib\site-packages\django\core\handlers\exception.py", line 47, in inner
    response = get_response(request)
               ^^^^^^^^^^^^^^^^^^^^^
  File "C:\Users\ASUS\anaconda3\Lib\site-packages\django\core\handlers\base.py", line 181, in _get_response
    response = wrapped_callback(request, *callback_args, **callback_kwargs)
               ^^^^^^^^^^^^^^^^^^^^^^^^^^^^^^^^^^^^^^^^^^^^^^^^^^^^^^^^^^^^
  File "C:\Users\ASUS\Desktop\HastaneYonetim\HastaneYonetimProjesi\hastane\views\appointment_views.py", line 124, in check_doctor_availability
    'speciality': doctor.speciality
                  ^^^^^^^^^^^^^^^^^
AttributeError: 'Doctors' object has no attribute 'speciality'
ERROR 2025-07-31 15:41:04,976 basehttp "GET /randevu/doktor-uygunluk/9/?date=2025-08-12&time=12%3A00&appointment_id= HTTP/1.1" 500 70901
